Workbook
Name 人类: 法术书目录!$AM$42
Name 阿斯莫: 法术书目录!$AM$43:$AO$43
Name 精灵: 法术书目录!$AM$44:$AW$44
Name 半身人: 法术书目录!$AM$45:$AO$45
Name 矮人: 法术书目录!$AM$46:$AO$46
Name 龙裔: 法术书目录!$AM$47:$AV$47
Name 侏儒: 法术书目录!$AM$48:$AO$48
Name 提夫林: 法术书目录!$AM$51:$AW$51
Name 元素裔: 法术书目录!$AM$53:$AP$53
Name 地精: 法术书目录!$AM$60:$AN$60
Name 吉斯人: 法术书目录!$AM$64:$AN$64
Name 化兽者: 法术书目录!$AM$72:$AP$72
Name 战俑: 法术书目录!$AM$73:$AO$73
Name 半精灵: 法术书目录!$AM$49:$AQ$49
Name 析米克杂种: 法术书目录!$AM$68:$AR$68

Sheet 背景
A1: 人物背景 Background
B3: 个性
B5: 理念
B6: 羁绊
B7: 缺陷
B9: 背景特性
B13: 外貌描写
AM15: 形象
B17: 背景故事 | AM17: 背景
AM18: 出身
AM20: 语言
AM27: 熟练工具

Sheet 主要
O1: DND 5E 人物卡 <NekoWorks ver2.1> | AG1: 推荐在电脑上使用Excel2010及以后版本打开本卡
Y2: Lv
B3: 角色名 | P3: 职业 | AA3: > | AB3: 熟练 | AD3: =IF(Y3<5,2,IF(Y3<9,3,IF(Y3<13,4,IF(Y3<17,5,6)))) -> 2
B4: 玩家 | P4: 经验值 | Y4: =IF(S4="","","Lv") | Z4: =IF(S4="","",VLOOKUP($S$4,法术书目录!$O$24:$P$43,2,TRUE))
B6: 种族 | J6: 性别 | Q6: 身高 | X6: 阵营
B7: 亚种 | J7: 年龄 | Q7: 体重 | X7: 信仰
B9: 属性 | N9: 战斗
B10: 熟练 | F10: 基本值 | I10: 调整值 | K10: 豁免 | S10: 其他 | Z10: Now | AC10: Max
A11: FALSE | C11: 力量 | F11: 10 | H11: > | I11: =INT(F11/2-5) -> 0 | K11: =INT(F11/2-5)+IF(A11=TRUE,$AD$3,0) -> 0 | N11: 先攻 | P11: =SUM(I13+S11) -> 0 | R11: < | V11: HP | Y11: 1 | AB11: / | AC11: 1
A13: FALSE | C13: 敏捷 | F13: 10 | H13: > | I13: =INT(F13/2-5) -> 0 | K13: =INT(F13/2-5)+IF(A13=TRUE,$AD$3,0) -> 0 | M13: > | N13: AC | P13: =SUM(AD26,IF(AG26<>"",AG26,I13),S13)+IF(DB!A25=TRUE,AP26,0) -> 10 | R13: < | V13: HD | X13: 1 | Z13: / | AA13: =IF(Y3<=0,"",Y3)
A15: FALSE | C15: 体质 | F15: 10 | H15: > | I15: =INT(F15/2-5) -> 0 | K15: =INT(F15/2-5)+IF(A15=TRUE,$AD$3,0) -> 0 | S15: 其他 | U15: 死亡豁免成功 | AB15: 失败
N16: DC | P16: =SUM(8+AD3+IF(R19="力量",I11,IF(R19="敏捷",I13,IF(R19="体质",I15,IF(R19="智力",I17,IF(R19="感知",I19,IF(R19="魅力",I21,0))))))) -> 10 | R16: < | V16: 特殊 | AB16: 临时 HP
A17: FALSE | C17: 智力 | F17: 10 | H17: > | I17: =INT(F17/2-5) -> 0 | K17: =INT(F17/2-5)+IF(A17=TRUE,$AD$3,0) -> 0
A19: FALSE | C19: 感知 | F19: 10 | H19: > | I19: =INT(F19/2-5) -> 0 | K19: =INT(F19/2-5)+IF(A19=TRUE,$AD$3,0) -> 0 | N19: 关键属性 | R19: 力量 | V19: 体型 | AB19: 速度
A21: FALSE | C21: 魅力 | F21: 10 | H21: > | I21: =INT(F21/2-5) -> 0 | K21: =INT(F21/2-5)+IF(A21=TRUE,$AD$3,0) -> 0 | N21: 被动察觉 | R21: =SUM(10+I38) -> 10 | V21: 抗力
AH22: 画像
B24: 技能 | S24: 装备 | X24: =IF(AB24="","","已同调的装备") | AB24: =IF(COUNTIF(法术书目录!R27:R42,TRUE)=0,"",COUNTIF(法术书目录!R27:R42,TRUE)) | AD24: 快捷战斗
B25: 熟练 | D25: 力量系 | F25: 修正 | I25: 总值 | L25: 护甲 | P25: 名称 | U25: 同调 | W25: 特性 | AA25: 重量 | AD25: AC | AF25: 最大敏捷 | AL25: 同调 | AM25: 盾牌 | AP25: AC | AR25: 重量
A26: FALSE | C26: 运动 | H26: > | I26: =$I$11+IF($A26=TRUE,$AD$3,0)+F26 -> 0 | L26: - | N26: > | AC26: > | AD26: 10 | AF26: +
B27: 敏捷系 | L27: 武器 | P27: 武器名称 | U27: 同调 | W27: 特性 | AA27: 重量 | AD27: 熟练 | AF27: 攻击骰 | AI27: 伤害骰 | AN27: 伤害类型 | AQ27: 弹药
A28: FALSE | C28: 特技 | H28: > | I28: =$I$13+IF($A28=TRUE,$AD$3,0)+F28 -> 0 | K28: FALSE | L28: - | N28: > | AC28: > | AE28: =IFERROR(CONCATENATE("D20",(IF($K28=TRUE,"+",IF(VLOOKUP(VLOOKUP($L28,法术书目录!$X$9:$AC$47,6,FALSE),$C$11:$L$22,7,FALSE)<0,"","+")))),"D20+") -> D20+ | AG28: =IFERROR(CONCATENATE(IF($K28=TRUE,$AD$3,""),IF(VLOOKUP(VLOOKUP($L28,法术书目录!$X$9:$AC$47,6,FALSE),$C$11:$L$22,7,FALSE)<0,"",(IF($K28=TRUE,"+",""))),VLOOKUP(VLOOKUP($L28,法术书目录!$X$9:$AC$47,6,FALSE),$C$11:$L$22,7,FALSE)),"") | AL28: =IFERROR(IF(AI28="","",CONCATENATE(IF(VLOOKUP(VLOOKUP($L28,法术书目录!$X$9:$AC$47,6,FALSE),$C$11:$L$22,7,FALSE)<0,"","+"),VLOOKUP(VLOOKUP($L28,法术书目录!$X$9:$AC$47,6,FALSE),$C$11:$L$22,7,FALSE))),"") | AQ28: 箭 | AR28: 0
A29: FALSE | C29: 巧手 | H29: > | I29: =$I$13+IF($A29=TRUE,$AD$3,0)+F29 -> 0 | K29: FALSE | L29: - | N29: > | AC29: > | AE29: =IFERROR(CONCATENATE("D20",(IF($K29=TRUE,"+",IF(VLOOKUP(VLOOKUP($L29,法术书目录!$X$9:$AC$47,6,FALSE),$C$11:$L$22,7,FALSE)<0,"","+")))),"D20+") -> D20+ | AG29: =IFERROR(CONCATENATE(IF($K29=TRUE,$AD$3,""),IF(VLOOKUP(VLOOKUP($L29,法术书目录!$X$9:$AC$47,6,FALSE),$C$11:$L$22,7,FALSE)<0,"",(IF($K29=TRUE,"+",""))),VLOOKUP(VLOOKUP($L29,法术书目录!$X$9:$AC$47,6,FALSE),$C$11:$L$22,7,FALSE)),"") | AL29: =IFERROR(IF(AI29="","",CONCATENATE(IF(VLOOKUP(VLOOKUP($L29,法术书目录!$X$9:$AC$47,6,FALSE),$C$11:$L$22,7,FALSE)<0,"","+"),VLOOKUP(VLOOKUP($L29,法术书目录!$X$9:$AC$47,6,FALSE),$C$11:$L$22,7,FALSE))),"") | AQ29: 矢 | AR29: 0
A30: FALSE | C30: 隐匿 | H30: > | I30: =$I$13+IF($A30=TRUE,$AD$3,0)+F30 -> 0 | K30: FALSE | L30: - | N30: > | AC30: > | AE30: =IFERROR(CONCATENATE("D20",(IF($K30=TRUE,"+",IF(VLOOKUP(VLOOKUP($L30,法术书目录!$X$9:$AC$47,6,FALSE),$C$11:$L$22,7,FALSE)<0,"","+")))),"D20+") -> D20+ | AG30: =IFERROR(CONCATENATE(IF($K30=TRUE,$AD$3,""),IF(VLOOKUP(VLOOKUP($L30,法术书目录!$X$9:$AC$47,6,FALSE),$C$11:$L$22,7,FALSE)<0,"",(IF($K30=TRUE,"+",""))),VLOOKUP(VLOOKUP($L30,法术书目录!$X$9:$AC$47,6,FALSE),$C$11:$L$22,7,FALSE)),"") | AL30: =IFERROR(IF(AI30="","",CONCATENATE(IF(VLOOKUP(VLOOKUP($L30,法术书目录!$X$9:$AC$47,6,FALSE),$C$11:$L$22,7,FALSE)<0,"","+"),VLOOKUP(VLOOKUP($L30,法术书目录!$X$9:$AC$47,6,FALSE),$C$11:$L$22,7,FALSE))),"") | AQ30: 弹 | AR30: 0
B31: 智力系 | K31: FALSE | L31: - | N31: > | AC31: > | AE31: =IFERROR(CONCATENATE("D20",(IF($K31=TRUE,"+",IF(VLOOKUP(VLOOKUP($L31,法术书目录!$X$9:$AC$47,6,FALSE),$C$11:$L$22,7,FALSE)<0,"","+")))),"D20+") -> D20+ | AG31: =IFERROR(CONCATENATE(IF($K31=TRUE,$AD$3,""),IF(VLOOKUP(VLOOKUP($L31,法术书目录!$X$9:$AC$47,6,FALSE),$C$11:$L$22,7,FALSE)<0,"",(IF($K31=TRUE,"+",""))),VLOOKUP(VLOOKUP($L31,法术书目录!$X$9:$AC$47,6,FALSE),$C$11:$L$22,7,FALSE)),"") | AL31: =IFERROR(IF(AI31="","",CONCATENATE(IF(VLOOKUP(VLOOKUP($L31,法术书目录!$X$9:$AC$47,6,FALSE),$C$11:$L$22,7,FALSE)<0,"","+"),VLOOKUP(VLOOKUP($L31,法术书目录!$X$9:$AC$47,6,FALSE),$C$11:$L$22,7,FALSE))),"") | AQ31: 投 | AR31: 0
A32: FALSE | C32: 调查 | H32: > | I32: =$I$17+IF($A32=TRUE,$AD$3,0)+F32 -> 0 | K32: FALSE | L32: - | N32: > | AC32: > | AE32: =IFERROR(CONCATENATE("D20",(IF($K32=TRUE,"+",IF(VLOOKUP(VLOOKUP($L32,法术书目录!$X$9:$AC$47,6,FALSE),$C$11:$L$22,7,FALSE)<0,"","+")))),"D20+") -> D20+ | AG32: =IFERROR(CONCATENATE(IF($K32=TRUE,$AD$3,""),IF(VLOOKUP(VLOOKUP($L32,法术书目录!$X$9:$AC$47,6,FALSE),$C$11:$L$22,7,FALSE)<0,"",(IF($K32=TRUE,"+",""))),VLOOKUP(VLOOKUP($L32,法术书目录!$X$9:$AC$47,6,FALSE),$C$11:$L$22,7,FALSE)),"") | AL32: =IFERROR(IF(AI32="","",CONCATENATE(IF(VLOOKUP(VLOOKUP($L32,法术书目录!$X$9:$AC$47,6,FALSE),$C$11:$L$22,7,FALSE)<0,"","+"),VLOOKUP(VLOOKUP($L32,法术书目录!$X$9:$AC$47,6,FALSE),$C$11:$L$22,7,FALSE))),"") | AQ32: 它 | AR32: 0
A33: FALSE | C33: 奥秘 | H33: > | I33: =$I$17+IF($A33=TRUE,$AD$3,0)+F33 -> 0 | L33: 其他 | P33: 名称 | U33: 同调 | W33: 特性 | AA33: 重量
A34: FALSE | C34: 历史 | H34: > | I34: =$I$17+IF($A34=TRUE,$AD$3,0)+F34 -> 0 | L34: - | N34: > | AD34: 法术
A35: FALSE | C35: 自然 | H35: > | I35: =$I$17+IF($A35=TRUE,$AD$3,0)+F35 -> 0 | L35: - | N35: > | AD35: 施法属性 | AH35: 法术基础攻击骰 | AN35: 可以准备的法术数量
A36: FALSE | C36: 宗教 | H36: > | I36: =$I$17+IF($A36=TRUE,$AD$3,0)+F36 -> 0 | L36: - | N36: > | AG36: > | AH36: =IFERROR(VLOOKUP(AD36,法术书目录!W49:Y51,3,FALSE),"") | AK36: =IFERROR(CONCATENATE(VLOOKUP(AD36,$C$11:$J$22,7,FALSE),"+",$AD$3),"") | AQ36: =IFERROR(VLOOKUP(AN36,法术书目录!$O$9:$P$20,2,FALSE),"")
B37: 感知系 | L37: - | N37: > | AF37: > | AG37: > | AH37: =IFERROR(VLOOKUP(AD37,法术书目录!W49:Y51,3,FALSE),"") | AK37: =IFERROR(CONCATENATE(VLOOKUP(AD37,$C$11:$J$22,7,FALSE),"+",$AD$3),"") | AQ37: =IFERROR(VLOOKUP(AN37,法术书目录!$O$9:$P$20,2,FALSE),"")
A38: FALSE | C38: 察觉 | H38: > | I38: =$I$19+IF($A38=TRUE,$AD$3,0)+F38 -> 0 | L38: - | N38: > | AO38: 法术位
A39: FALSE | C39: 洞悉 | H39: > | I39: =$I$19+IF($A39=TRUE,$AD$3,0)+F39 -> 0 | L39: - | N39: > | AD39: 关键属性 | AI39: 智力 | AM39: 1 | AQ39: /
A40: FALSE | C40: 驯养 | H40: > | I40: =$I$19+IF($A40=TRUE,$AD$3,0)+F40 -> 0 | L40: - | N40: > | AD40: 法术DC | AI40: =SUM(8+AD3+IF(AI39="智力",I17,IF(AI39="感知",I19,IF(AI39="魅力",I21,)))) -> 10 | AM40: 2 | AQ40: /
A41: FALSE | C41: 医疗 | H41: > | I41: =$I$19+IF($A41=TRUE,$AD$3,0)+F41 -> 0 | L41: - | N41: > | AM41: 3 | AQ41: /
A42: FALSE | C42: 生存 | H42: > | I42: =$I$19+IF($A42=TRUE,$AD$3,0)+F42 -> 0 | L42: - | N42: > | AE42: ———随身钱币——— | AM42: 4 | AQ42: /
B43: 魅力系 | L43: 负重规则 | O43: 5 | R43: ——负重&财产—— | AE43: PP | AM43: 5 | AQ43: /
A44: FALSE | C44: 说服 | H44: > | I44: =$I$21+IF($A44=TRUE,$AD$3,0)+F44 -> 0 | L44: 装备 | O44: 背包1 | R44: 背包2 | U44: > | V44: 总负重 | Z44: < | AA44: 钱包 | AD44: < | AE44: EP | AM44: 6 | AQ44: /
A45: FALSE | C45: 欺诈 | H45: > | I45: =$I$21+IF($A45=TRUE,$AD$3,0)+F45 -> 0 | L45: =SUM(AA34:AB42,AA28:AB32,AA26,AR26) -> 0 | O45: =背包!V3 -> 0 | R45: =背包!AS3 -> 0 | V45: =SUM(L45:T45)+AA45+AA47 -> 0 | AA45: =SUM(AG43:AK47)/50 -> 0 | AE45: GP | AM45: 7 | AQ45: /
A46: FALSE | C46: 威吓 | H46: > | I46: =$I$21+IF($A46=TRUE,$AD$3,0)+F46 -> 0 | L46: 轻载 | O46: 中载 | R46: 重载 | V46: 状态 | AA46: 次元袋 | AE46: SP | AM46: 8 | AQ46: /
A47: FALSE | C47: 表演 | H47: > | I47: =$I$21+IF($A47=TRUE,$AD$3,0)+F47 -> 0 | L47: =F11*O43 -> 50 | O47: =F11*O43*2 -> 100 | R47: =F11*O43*3 -> 150 | V47: =IF(V45<=L47,"轻载",IF(V45<=O47,"中载",IF(V45<=R47,"重载","重载"))) -> 轻载 | AA47: =IF(背包!V27="无效",0,15)+IF(背包!AS27="无效",0,15) -> 0 | AE47: CP | AM47: 9 | AQ47: /
...

Sheet 法术书目录
A1: 1 | B1: =IF(法术书I!W8="","",法术书I!W8) | C1: =IFERROR(VLOOKUP(B1,列表!$B:$B,1,FALSE),"QuQ") -> QuQ | D1: =IFERROR(VLOOKUP(C1,列表!$B:$T,17,FALSE),"") | E1: 1 | F1: =IF(法术书II!W8="","",法术书II!W8) | G1: =IFERROR(VLOOKUP(F1,列表!$B:$B,1,FALSE),"QuQ") -> QuQ | H1: =IFERROR(VLOOKUP(G1,列表!$B:$T,17,FALSE),"") | I1: 1 | J1: =IF(法术书III!W8="","",法术书III!W8) | K1: =IFERROR(VLOOKUP(J1,列表!$B:$B,1,FALSE),"QuQ") -> QuQ | L1: =IFERROR(VLOOKUP(K1,列表!$B:$T,17,FALSE),"") | N1: I | O1: 1 | Q1: 戏法 | R1: 0 | T1: 货币 | U1: 铜币CP | V1: 银币SP | W1: 金银币EP | X1: 金币GP | Y1: 白金币PP
A2: 2 | B2: =IF(法术书I!W9="","",法术书I!W9) | C2: =IFERROR(VLOOKUP(B2,列表!$B:$B,1,FALSE),"QuQ") -> QuQ | D2: =IFERROR(VLOOKUP(C2,列表!$B:$T,17,FALSE),"") | E2: 2 | F2: =IF(法术书II!W9="","",法术书II!W9) | G2: =IFERROR(VLOOKUP(F2,列表!$B:$B,1,FALSE),"QuQ") -> QuQ | H2: =IFERROR(VLOOKUP(G2,列表!$B:$T,17,FALSE),"") | I2: 2 | J2: =IF(法术书III!W9="","",法术书III!W9) | K2: =IFERROR(VLOOKUP(J2,列表!$B:$B,1,FALSE),"QuQ") -> QuQ | L2: =IFERROR(VLOOKUP(K2,列表!$B:$T,17,FALSE),"") | N2: II | O2: 1 | Q2: 1环 | R2: 1 | T2: 铜币CP | U2: 1 | V2: =1/10 -> 0.1 | W2: =1/50 -> 0.02 | X2: =1/100 -> 0.01 | Y2: =1/1000 -> 0.001 | Z2: 1
A3: 3 | B3: =IF(法术书I!W10="","",法术书I!W10) | C3: =IFERROR(VLOOKUP(B3,列表!$B:$B,1,FALSE),"QuQ") -> QuQ | D3: =IFERROR(VLOOKUP(C3,列表!$B:$T,17,FALSE),"") | E3: 3 | F3: =IF(法术书II!W10="","",法术书II!W10) | G3: =IFERROR(VLOOKUP(F3,列表!$B:$B,1,FALSE),"QuQ") -> QuQ | H3: =IFERROR(VLOOKUP(G3,列表!$B:$T,17,FALSE),"") | I3: 3 | J3: =IF(法术书III!W10="","",法术书III!W10) | K3: =IFERROR(VLOOKUP(J3,列表!$B:$B,1,FALSE),"QuQ") -> QuQ | L3: =IFERROR(VLOOKUP(K3,列表!$B:$T,17,FALSE),"") | N3: II | O3: 1 | Q3: 2环 | R3: 2 | T3: 银币SP | U3: 10 | V3: 1 | W3: =1/5 -> 0.2 | X3: =1/10 -> 0.1 | Y3: =1/100 -> 0.01 | Z3: 2
A4: 4 | B4: =IF(法术书I!W11="","",法术书I!W11) | C4: =IFERROR(VLOOKUP(B4,列表!$B:$B,1,FALSE),"QuQ") -> QuQ | D4: =IFERROR(VLOOKUP(C4,列表!$B:$T,17,FALSE),"") | E4: 4 | F4: =IF(法术书II!W11="","",法术书II!W11) | G4: =IFERROR(VLOOKUP(F4,列表!$B:$B,1,FALSE),"QuQ") -> QuQ | H4: =IFERROR(VLOOKUP(G4,列表!$B:$T,17,FALSE),"") | I4: 4 | J4: =IF(法术书III!W11="","",法术书III!W11) | K4: =IFERROR(VLOOKUP(J4,列表!$B:$B,1,FALSE),"QuQ") -> QuQ | L4: =IFERROR(VLOOKUP(K4,列表!$B:$T,17,FALSE),"") | Q4: 3环 | R4: 3 | T4: 金银币EP | U4: 50 | V4: 5 | W4: 1 | X4: =1/2 -> 0.5 | Y4: =1/20 -> 0.05 | Z4: 3
A5: 5 | B5: =IF(法术书I!W12="","",法术书I!W12) | C5: =IFERROR(VLOOKUP(B5,列表!$B:$B,1,FALSE),"QuQ") -> QuQ | D5: =IFERROR(VLOOKUP(C5,列表!$B:$T,17,FALSE),"") | E5: 5 | F5: =IF(法术书II!W12="","",法术书II!W12) | G5: =IFERROR(VLOOKUP(F5,列表!$B:$B,1,FALSE),"QuQ") -> QuQ | H5: =IFERROR(VLOOKUP(G5,列表!$B:$T,17,FALSE),"") | I5: 5 | J5: =IF(法术书III!W12="","",法术书III!W12) | K5: =IFERROR(VLOOKUP(J5,列表!$B:$B,1,FALSE),"QuQ") -> QuQ | L5: =IFERROR(VLOOKUP(K5,列表!$B:$T,17,FALSE),"") | O5: V 言语 | Q5: 4环 | R5: 4 | T5: 金币GP | U5: 100 | V5: 10 | W5: 2 | X5: 1 | Y5: =1/10 -> 0.1 | Z5: 4
A6: 6 | B6: =IF(法术书I!W13="","",法术书I!W13) | C6: =IFERROR(VLOOKUP(B6,列表!$B:$B,1,FALSE),"QuQ") -> QuQ | D6: =IFERROR(VLOOKUP(C6,列表!$B:$T,17,FALSE),"") | E6: 6 | F6: =IF(法术书II!W13="","",法术书II!W13) | G6: =IFERROR(VLOOKUP(F6,列表!$B:$B,1,FALSE),"QuQ") -> QuQ | H6: =IFERROR(VLOOKUP(G6,列表!$B:$T,17,FALSE),"") | I6: 6 | J6: =IF(法术书III!W13="","",法术书III!W13) | K6: =IFERROR(VLOOKUP(J6,列表!$B:$B,1,FALSE),"QuQ") -> QuQ | L6: =IFERROR(VLOOKUP(K6,列表!$B:$T,17,FALSE),"") | O6: S 姿势 | Q6: 5环 | R6: 5 | T6: 白金币PP | U6: 1000 | V6: 100 | W6: 20 | X6: 10 | Y6: 1 | Z6: 5
A7: 7 | B7: =IF(法术书I!W14="","",法术书I!W14) | C7: =IFERROR(VLOOKUP(B7,列表!$B:$B,1,FALSE),"QuQ") -> QuQ | D7: =IFERROR(VLOOKUP(C7,列表!$B:$T,17,FALSE),"") | E7: 7 | F7: =IF(法术书II!W14="","",法术书II!W14) | G7: =IFERROR(VLOOKUP(F7,列表!$B:$B,1,FALSE),"QuQ") -> QuQ | H7: =IFERROR(VLOOKUP(G7,列表!$B:$T,17,FALSE),"") | I7: 7 | J7: =IF(法术书III!W14="","",法术书III!W14) | K7: =IFERROR(VLOOKUP(J7,列表!$B:$B,1,FALSE),"QuQ") -> QuQ | L7: =IFERROR(VLOOKUP(K7,列表!$B:$T,17,FALSE),"") | O7: M 材料 | Q7: 6环 | R7: 6 | U7: 1 | V7: 2 | W7: 3 | X7: 4 | Y7: 5
A8: 8 | B8: =IF(法术书I!W15="","",法术书I!W15) | C8: =IFERROR(VLOOKUP(B8,列表!$B:$B,1,FALSE),"QuQ") -> QuQ | D8: =IFERROR(VLOOKUP(C8,列表!$B:$T,17,FALSE),"") | E8: 8 | F8: =IF(法术书II!W15="","",法术书II!W15) | G8: =IFERROR(VLOOKUP(F8,列表!$B:$B,1,FALSE),"QuQ") -> QuQ | H8: =IFERROR(VLOOKUP(G8,列表!$B:$T,17,FALSE),"") | I8: 8 | J8: =IF(法术书III!W15="","",法术书III!W15) | K8: =IFERROR(VLOOKUP(J8,列表!$B:$B,1,FALSE),"QuQ") -> QuQ | L8: =IFERROR(VLOOKUP(K8,列表!$B:$T,17,FALSE),"") | Q8: 7环 | R8: 7
A9: 9 | B9: =IF(法术书I!W16="","",法术书I!W16) | C9: =IFERROR(VLOOKUP(B9,列表!$B:$B,1,FALSE),"QuQ") -> QuQ | D9: =IFERROR(VLOOKUP(C9,列表!$B:$T,17,FALSE),"") | E9: 9 | F9: =IF(法术书II!W16="","",法术书II!W16) | G9: =IFERROR(VLOOKUP(F9,列表!$B:$B,1,FALSE),"QuQ") -> QuQ | H9: =IFERROR(VLOOKUP(G9,列表!$B:$T,17,FALSE),"") | I9: 9 | J9: =IF(法术书III!W16="","",法术书III!W16) | K9: =IFERROR(VLOOKUP(J9,列表!$B:$B,1,FALSE),"QuQ") -> QuQ | L9: =IFERROR(VLOOKUP(K9,列表!$B:$T,17,FALSE),"") | O9: 野蛮人 | P9: 0v0？ | Q9: 8环 | R9: 8 | T9: - | U9: - | V9: ="" | X9: 名称 | Y9: 价格 | Z9: 伤害 | AA9: 重量 | AB9: 特质 | AG9: 力量 | AH9: 敏捷 | AI9: 体质 | AJ9: 智力 | AK9: 感知 | AL9: 魅力
A10: 10 | B10: =IF(法术书I!W17="","",法术书I!W17) | C10: =IFERROR(VLOOKUP(B10,列表!$B:$B,1,FALSE),"QuQ") -> QuQ | D10: =IFERROR(VLOOKUP(C10,列表!$B:$T,17,FALSE),"") | E10: 10 | F10: =IF(法术书II!W17="","",法术书II!W17) | G10: =IFERROR(VLOOKUP(F10,列表!$B:$B,1,FALSE),"QuQ") -> QuQ | H10: =IFERROR(VLOOKUP(G10,列表!$B:$T,17,FALSE),"") | I10: 10 | J10: =IF(法术书III!W17="","",法术书III!W17) | K10: =IFERROR(VLOOKUP(J10,列表!$B:$B,1,FALSE),"QuQ") -> QuQ | L10: =IFERROR(VLOOKUP(K10,列表!$B:$T,17,FALSE),"") | O10: 吟游诗人 | P10: 0v0？ | Q10: 9环 | R10: 9 | T10: 全头 | U10: 轻型 | V10: ="" | X10: - | AE10: 1 | AF10: 1 | AG10: 你还有呼吸的力气 | AH10: 一动不动 | AI10: 应该还算活着 | AJ10: 蚂蚁的智力都不可能是1 | AK10: 你是怎么活到现在的 | AL10: 用脸就能恐惧敌人
A11: 11 | B11: =IF(法术书I!W18="","",法术书I!W18) | C11: =IFERROR(VLOOKUP(B11,列表!$B:$B,1,FALSE),"QuQ") -> QuQ | D11: =IFERROR(VLOOKUP(C11,列表!$B:$T,17,FALSE),"") | E11: 11 | F11: =IF(法术书II!W18="","",法术书II!W18) | G11: =IFERROR(VLOOKUP(F11,列表!$B:$B,1,FALSE),"QuQ") -> QuQ | H11: =IFERROR(VLOOKUP(G11,列表!$B:$T,17,FALSE),"") | I11: 11 | J11: =IF(法术书III!W18="","",法术书III!W18) | K11: =IFERROR(VLOOKUP(J11,列表!$B:$B,1,FALSE),"QuQ") -> QuQ | L11: =IFERROR(VLOOKUP(K11,列表!$B:$T,17,FALSE),"") | O11: 战士 | P11: 0v0？ | T11: 头部 | U11: 中型 | W11: 简单近战武器 | X11: 短棒 | Y11: 1sp | Z11: 1d4钝击 | AA11: 2lb | AB11: 轻 | AC11: 力量 | AF11: 2 | AG11: 连一枚金币都拿不起来 | AH11: 残疾人士 | AI11: 固有Buff：病弱 | AJ11: 连说话都困难 | AK11: 迷惘的人啊 | AL11: 你出生的时候居然没被掐死
A12: 12 | B12: =IF(法术书I!W19="","",法术书I!W19) | C12: =IFERROR(VLOOKUP(B12,列表!$B:$B,1,FALSE),"QuQ") -> QuQ | D12: =IFERROR(VLOOKUP(C12,列表!$B:$T,17,FALSE),"") | E12: 12 | F12: =IF(法术书II!W19="","",法术书II!W19) | G12: =IFERROR(VLOOKUP(F12,列表!$B:$B,1,FALSE),"QuQ") -> QuQ | H12: =IFERROR(VLOOKUP(G12,列表!$B:$T,17,FALSE),"") | I12: 12 | J12: =IF(法术书III!W19="","",法术书III!W19) | K12: =IFERROR(VLOOKUP(J12,列表!$B:$B,1,FALSE),"QuQ") -> QuQ | L12: =IFERROR(VLOOKUP(K12,列表!$B:$T,17,FALSE),"") | O12: 牧师 | P12: =主要!I19+主要!Y3 -> 0 | Q12: - | R12: 死亡豁免失败 | T12: 头发 | U12: 重型 | X12: 匕首 | Y12: 2gp | Z12: 1d4穿刺 | AA12: 1lb | AB12: 灵巧，轻，投掷（射程20/60） | AC12: =IF(主要!$I$11>=主要!$I$13,"力量","敏捷") -> 力量 | AF12: 3 | AG12: 鸡的力量都比你强 | AH12: 无法行动自如 | AI12: 突然挂掉都不是奇怪的事情 | AJ12: 目不识丁 | AK12: 上错过厕所 | AL12: 路边的狗可能会冲过来咬你
A13: 13 | B13: =IF(法术书I!W20="","",法术书I!W20) | C13: =IFERROR(VLOOKUP(B13,列表!$B:$B,1,FALSE),"QuQ") -> QuQ | D13: =IFERROR(VLOOKUP(C13,列表!$B:$T,17,FALSE),"") | E13: 13 | F13: =IF(法术书II!W20="","",法术书II!W20) | G13: =IFERROR(VLOOKUP(F13,列表!$B:$B,1,FALSE),"QuQ") -> QuQ | H13: =IFERROR(VLOOKUP(G13,列表!$B:$T,17,FALSE),"") | I13: 13 | J13: =IF(法术书III!W20="","",法术书III!W20) | K13: =IFERROR(VLOOKUP(J13,列表!$B:$B,1,FALSE),"QuQ") -> QuQ | L13: =IFERROR(VLOOKUP(K13,列表!$B:$T,17,FALSE),"") | O13: 圣武士 | P13: =主要!I19+INT(主要!Y3/2) -> 0 | Q13: 男 | R13: FALSE | T13: 面部 | U13: 盾牌 | X13: 巨棒 | Y13: 2sp | Z13: 1d8钝击 | AA13: 10lb | AB13: 双手 | AC13: 力量 | AE13: 2 | AF13: 4 | AG13: 手无抓鸡之力 | AH13: 腿脚不灵活 | AI13: 您的每一天都是上天的恩赐 | AJ13: 你能看得懂这行字？ | AK13: 经常迷路 | AL13: 容易被排斥
A14: 14 | B14: =IF(法术书I!W21="","",法术书I!W21) | C14: =IFERROR(VLOOKUP(B14,列表!$B:$B,1,FALSE),"QuQ") -> QuQ | D14: =IFERROR(VLOOKUP(C14,列表!$B:$T,17,FALSE),"") | E14: 14 | F14: =IF(法术书II!W21="","",法术书II!W21) | G14: =IFERROR(VLOOKUP(F14,列表!$B:$B,1,FALSE),"QuQ") -> QuQ | H14: =IFERROR(VLOOKUP(G14,列表!$B:$T,17,FALSE),"") | I14: 14 | J14: =IF(法术书III!W21="","",法术书III!W21) | K14: =IFERROR(VLOOKUP(J14,列表!$B:$B,1,FALSE),"QuQ") -> QuQ | L14: =IFERROR(VLOOKUP(K14,列表!$B:$T,17,FALSE),"") | O14: 德鲁伊 | P14: =主要!I19+主要!Y3 -> 0 | Q14: 女 | R14: FALSE | T14: 颈部 | U14: 穿刺 | X14: 手斧 | Y14: 5gp | Z14: 1d6挥砍 | AA14: 2lb | AB14: 轻，投掷（射程20/60） | AC14: 力量 | AF14: 5 | AG14: 恭喜你超越了鸡的力量 | AH14: 平地摔是你的家常便饭 | AI14: 常年病痛缠身 | AJ14: 阿库娅与你同在 | AK14: 在楼房里面找不到房间 | AL14: 可能会被人刁难
A15: 15 | B15: =IF(法术书I!W22="","",法术书I!W22) | C15: =IFERROR(VLOOKUP(B15,列表!$B:$B,1,FALSE),"QuQ") -> QuQ | D15: =IFERROR(VLOOKUP(C15,列表!$B:$T,17,FALSE),"") | E15: 15 | F15: =IF(法术书II!W22="","",法术书II!W22) | G15: =IFERROR(VLOOKUP(F15,列表!$B:$B,1,FALSE),"QuQ") -> QuQ | H15: =IFERROR(VLOOKUP(G15,列表!$B:$T,17,FALSE),"") | I15: 15 | J15: =IF(法术书III!W22="","",法术书III!W22) | K15: =IFERROR(VLOOKUP(J15,列表!$B:$B,1,FALSE),"QuQ") -> QuQ | L15: =IFERROR(VLOOKUP(K15,列表!$B:$T,17,FALSE),"") | O15: 武僧 | P15: 0v0？ | Q15: 扶她 | R15: FALSE | T15: 身体 | U15: 挥砍 | X15: 标枪 | Y15: 5sp | Z15: 1d6穿刺 | AA15: 2lb | AB15: 投掷（射程30/120） | AC15: 力量 | AF15: 6 | AG15: 拿多点东西都气喘吁吁 | AH15: 经常莫名其妙的撞上什么 | AI15: 经常需要躺下休息 | AJ15: 学不下什么东西 | AK15: 东西放在眼前就是找不到 | AL15: 可能会受到种种审视
A16: 16 | B16: =IF(法术书I!W23="","",法术书I!W23) | C16: =IFERROR(VLOOKUP(B16,列表!$B:$B,1,FALSE),"QuQ") -> QuQ | D16: =IFERROR(VLOOKUP(C16,列表!$B:$T,17,FALSE),"") | E16: 16 | F16: =IF(法术书II!W23="","",法术书II!W23) | G16: =IFERROR(VLOOKUP(F16,列表!$B:$B,1,FALSE),"QuQ") -> QuQ | H16: =IFERROR(VLOOKUP(G16,列表!$B:$T,17,FALSE),"") | I16: 16 | J16: =IF(法术书III!W23="","",法术书III!W23) | K16: =IFERROR(VLOOKUP(J16,列表!$B:$B,1,FALSE),"QuQ") -> QuQ | L16: =IFERROR(VLOOKUP(K16,列表!$B:$T,17,FALSE),"") | O16: 术士 | P16: 0v0？ | Q16: 秀吉 | R16: =COUNTIF(R13:R15,TRUE) -> 0 | T16: 肩膀 | U16: 钝击 | X16: 轻锤 | Y16: 2gp | Z16: 1d4钝击 | AA16: 2lb | AB16: 轻，投掷（射程20/60） | AC16: 力量 | AE16: 3 | AF16: 7 | AG16: 穿脱衣服都有些吃力 | AH16: 走在平地上都会摔倒 | AI16: 可能有贫血什么的 | AJ16: 没有受过太多的教育 | AK16: 偶尔会犯迷糊 | AL16: 所有的人都觉得可以轻而易举地说服你
A17: 17 | B17: =IF(法术书I!W24="","",法术书I!W24) | C17: =IFERROR(VLOOKUP(B17,列表!$B:$B,1,FALSE),"QuQ") -> QuQ | D17: =IFERROR(VLOOKUP(C17,列表!$B:$T,17,FALSE),"") | E17: 17 | F17: =IF(法术书II!W24="","",法术书II!W24) | G17: =IFERROR(VLOOKUP(F17,列表!$B:$B,1,FALSE),"QuQ") -> QuQ | H17: =IFERROR(VLOOKUP(G17,列表!$B:$T,17,FALSE),"") | I17: 17 | J17: =IF(法术书III!W24="","",法术书III!W24) | K17: =IFERROR(VLOOKUP(J17,列表!$B:$B,1,FALSE),"QuQ") -> QuQ | L17: =IFERROR(VLOOKUP(K17,列表!$B:$T,17,FALSE),"") | O17: 游荡者 | P17: 0v0？ | Q17: 朕 | T17: 胸前 | U17: 冷冻 | X17: 硬头锤 | Y17: 5gp | Z17: 1d6钝击 | AA17: 4lb | AB17: - | AC17: 力量 | AF17: 8 | AG17: 你揍人就像在给对方按摩 | AH17: 不上不下真尴尬 | AI17: 健康状况堪忧 | AJ17: 你可能会怀疑你是不是健忘 | AK17: 关键时刻掉链子 | AL17: 你的说服力还是可以的
A18: 18 | B18: =IF(法术书I!W25="","",法术书I!W25) | C18: =IFERROR(VLOOKUP(B18,列表!$B:$B,1,FALSE),"QuQ") -> QuQ | D18: =IFERROR(VLOOKUP(C18,列表!$B:$T,17,FALSE),"") | E18: 18 | F18: =IF(法术书II!W25="","",法术书II!W25) | G18: =IFERROR(VLOOKUP(F18,列表!$B:$B,1,FALSE),"QuQ") -> QuQ | H18: =IFERROR(VLOOKUP(G18,列表!$B:$T,17,FALSE),"") | I18: 18 | J18: =IF(法术书III!W25="","",法术书III!W25) | K18: =IFERROR(VLOOKUP(J18,列表!$B:$B,1,FALSE),"QuQ") -> QuQ | L18: =IFERROR(VLOOKUP(K18,列表!$B:$T,17,FALSE),"") | O18: 法师 | P18: =主要!I17+主要!Y3 -> 0 | R18: 体型 | T18: 背后 | U18: 火焰 | X18: 木棍 | Y18: 2sp | Z18: 1d6钝击 | AA18: 4lb | AB18: 多用途(1d8) | AC18: 力量 | AF18: 9 | AG18: 比正常人稍微差一点 | AH18: 比正常人稍微差一点 | AI18: 比正常人稍微差一点 | AJ18: 思维比别人慢一拍 | AK18: 比正常人稍微差一点 | AL18: 比正常人稍微差一点
A19: 19 | B19: =IF(法术书I!W26="","",法术书I!W26) | C19: =IFERROR(VLOOKUP(B19,列表!$B:$B,1,FALSE),"QuQ") -> QuQ | D19: =IFERROR(VLOOKUP(C19,列表!$B:$T,17,FALSE),"") | E19: 19 | F19: =IF(法术书II!W26="","",法术书II!W26) | G19: =IFERROR(VLOOKUP(F19,列表!$B:$B,1,FALSE),"QuQ") -> QuQ | H19: =IFERROR(VLOOKUP(G19,列表!$B:$T,17,FALSE),"") | I19: 19 | J19: =IF(法术书III!W26="","",法术书III!W26) | K19: =IFERROR(VLOOKUP(J19,列表!$B:$B,1,FALSE),"QuQ") -> QuQ | L19: =IFERROR(VLOOKUP(K19,列表!$B:$T,17,FALSE),"") | O19: 游侠 | P19: 0v0？ | R19: 微型 | T19: 腰部 | U19: 闪电 | X19: 镰刀 | Y19: 1gp | Z19: 1d4挥砍 | AA19: 2lb | AB19: 轻 | AC19: 力量 | AE19: 4 | AF19: 10 | AG19: 有正常人的力量 | AH19: 普通人的水准 | AI19: 正常人的体质 | AJ19: 正常人的智力 | AK19: 你醒啦，你很正常 | AL19: 讨价还价的能力不错
A20: 20 | B20: =IF(法术书I!W27="","",法术书I!W27) | C20: =IFERROR(VLOOKUP(B20,列表!$B:$B,1,FALSE),"QuQ") -> QuQ | D20: =IFERROR(VLOOKUP(C20,列表!$B:$T,17,FALSE),"") | E20: 20 | F20: =IF(法术书II!W27="","",法术书II!W27) | G20: =IFERROR(VLOOKUP(F20,列表!$B:$B,1,FALSE),"QuQ") -> QuQ | H20: =IFERROR(VLOOKUP(G20,列表!$B:$T,17,FALSE),"") | I20: 20 | J20: =IF(法术书III!W27="","",法术书III!W27) | K20: =IFERROR(VLOOKUP(J20,列表!$B:$B,1,FALSE),"QuQ") -> QuQ | L20: =IFERROR(VLOOKUP(K20,列表!$B:$T,17,FALSE),"") | O20: 邪术师 | P20: 0v0？ | R20: 小型 | T20: 胯间 | U20: 力场 | X20: 矛 | Y20: 1gp | Z20: 1d6穿刺 | AA20: 3lb | AB20: 投掷（射程20/60），多用途(1d8) | AC20: 力量 | AF20: 11 | AG20: 在这个档次，做到欺软怕硬是没有问题的 | AH20: 可以徒手抓住苍蝇 | AI20: 疾病对于您来说，应该是偶发事故 | AJ20: 可以耍耍小聪明 | AK20: 找东西的时候方便一些 | AL20: 可以很容易地虎躯一震
A21: 21 | B21: =IF(法术书I!W28="","",法术书I!W28) | C21: =IFERROR(VLOOKUP(B21,列表!$B:$B,1,FALSE),"QuQ") -> QuQ | D21: =IFERROR(VLOOKUP(C21,列表!$B:$T,17,FALSE),"") | E21: 21 | F21: =IF(法术书II!W28="","",法术书II!W28) | G21: =IFERROR(VLOOKUP(F21,列表!$B:$B,1,FALSE),"QuQ") -> QuQ | H21: =IFERROR(VLOOKUP(G21,列表!$B:$T,17,FALSE),"") | I21: 21 | J21: =IF(法术书III!W28="","",法术书III!W28) | K21: =IFERROR(VLOOKUP(J21,列表!$B:$B,1,FALSE),"QuQ") -> QuQ | L21: =IFERROR(VLOOKUP(K21,列表!$B:$T,17,FALSE),"") | R21: 中型 | T21: 左脚 | U21: 光耀 | V21: - | W21: 简单远程武器 | X21: 轻弩 | Y21: 25gp | Z21: 1d8穿刺 | AA21: 5lb | AB21: 弹药（射程80/320），装填，双手 | AC21: 敏捷 | AF21: 12 | AG21: 经常锻炼的人能够达到的水平，可以很轻松地连续做上50个俯卧撑 | AH21: 可以用筷子夹住苍蝇 | AI21: 基本上没有吃过什么药，不是说不得病，但基本上抗一抗就过去了 | AJ21: 人才啊 | AK21: 可以注意到别人注意不到的细节 | AL21: 勉勉强强可以放出一丝王霸之气
A22: 22 | B22: =IF(法术书I!W29="","",法术书I!W29) | C22: =IFERROR(VLOOKUP(B22,列表!$B:$B,1,FALSE),"QuQ") -> QuQ | D22: =IFERROR(VLOOKUP(C22,列表!$B:$T,17,FALSE),"") | E22: 22 | F22: =IF(法术书II!W29="","",法术书II!W29) | G22: =IFERROR(VLOOKUP(F22,列表!$B:$B,1,FALSE),"QuQ") -> QuQ | H22: =IFERROR(VLOOKUP(G22,列表!$B:$T,17,FALSE),"") | I22: 22 | J22: =IF(法术书III!W29="","",法术书III!W29) | K22: =IFERROR(VLOOKUP(J22,列表!$B:$B,1,FALSE),"QuQ") -> QuQ | L22: =IFERROR(VLOOKUP(K22,列表!$B:$T,17,FALSE),"") | O22: 经验值 | R22: 大型 | T22: 右脚 | U22: 黯蚀 | V22: √ | X22: 飞镖 | Y22: 5cp | Z22: 1d4穿刺 | AA22: 1/4lb | AB22: 灵巧，投掷(射程20/60) | AC22: =IF(主要!$I$11>=主要!$I$13,"力量","敏捷") -> 力量 | AE22: 5 | AF22: 13 | AG22: 一拳一个小朋友 | AH22: 很不错的反应能力，可以在旋转的硬币落下的一瞬间看出是哪面落地 | AI22: 一般的磕磕碰碰都不放在眼里 | AJ22: 可以很轻松地取得别人要刻苦努力才能得到的成绩 | AK22: 可以推断出一些别人不知道的东西 | AL22: 人们更容易接受你的意见
A23: 23 | B23: =IF(法术书I!W30="","",法术书I!W30) | C23: =IFERROR(VLOOKUP(B23,列表!$B:$B,1,FALSE),"QuQ") -> QuQ | D23: =IFERROR(VLOOKUP(C23,列表!$B:$T,17,FALSE),"") | E23: 23 | F23: =IF(法术书II!W30="","",法术书II!W30) | G23: =IFERROR(VLOOKUP(F23,列表!$B:$B,1,FALSE),"QuQ") -> QuQ | H23: =IFERROR(VLOOKUP(G23,列表!$B:$T,17,FALSE),"") | I23: 23 | J23: =IF(法术书III!W30="","",法术书III!W30) | K23: =IFERROR(VLOOKUP(J23,列表!$B:$B,1,FALSE),"QuQ") -> QuQ | L23: =IFERROR(VLOOKUP(K23,列表!$B:$T,17,FALSE),"") | O23: Exp | P23: Lv | R23: 巨型 | T23: 双脚 | U23: 毒素 | X23: 短弓 | Y23: 25gp | Z23: 1d6穿刺 | AA23: 2lb | AB23: 弹药（射程80/320），双手 | AC23: 敏捷 | AF23: 14
A24: 24 | B24: =IF(法术书I!W31="","",法术书I!W31) | C24: =IFERROR(VLOOKUP(B24,列表!$B:$B,1,FALSE),"QuQ") -> QuQ | D24: =IFERROR(VLOOKUP(C24,列表!$B:$T,17,FALSE),"") | E24: 24 | F24: =IF(法术书II!W31="","",法术书II!W31) | G24: =IFERROR(VLOOKUP(F24,列表!$B:$B,1,FALSE),"QuQ") -> QuQ | H24: =IFERROR(VLOOKUP(G24,列表!$B:$T,17,FALSE),"") | I24: 24 | J24: =IF(法术书III!W31="","",法术书III!W31) | K24: =IFERROR(VLOOKUP(J24,列表!$B:$B,1,FALSE),"QuQ") -> QuQ | L24: =IFERROR(VLOOKUP(K24,列表!$B:$T,17,FALSE),"") | O24: 0 | P24: 1 | R24: 超巨型 | T24: 左腿 | U24: 精神 | X24: 投石索 | Y24: 1sp | Z24: 1d4钝击 | AA24: - | AB24: 弹药（射程30/120） | AC24: 敏捷 | AF24: 15
A25: 25 | B25: =IF(法术书I!W32="","",法术书I!W32) | C25: =IFERROR(VLOOKUP(B25,列表!$B:$B,1,FALSE),"QuQ") -> QuQ | D25: =IFERROR(VLOOKUP(C25,列表!$B:$T,17,FALSE),"") | E25: 25 | F25: =IF(法术书II!W32="","",法术书II!W32) | G25: =IFERROR(VLOOKUP(F25,列表!$B:$B,1,FALSE),"QuQ") -> QuQ | H25: =IFERROR(VLOOKUP(G25,列表!$B:$T,17,FALSE),"") | I25: 25 | J25: =IF(法术书III!W32="","",法术书III!W32) | K25: =IFERROR(VLOOKUP(J25,列表!$B:$B,1,FALSE),"QuQ") -> QuQ | L25: =IFERROR(VLOOKUP(K25,列表!$B:$T,17,FALSE),"") | O25: 300 | P25: 2 | T25: 右腿 | U25: 雷呜 | W25: 军用近战武器 | X25: 战斧 | Y25: 10gp | Z25: 1d8挥砍 | AA25: 4lb | AB25: 多用途(1d10) | AC25: 力量 | AE25: 6 | AF25: 16 | AG25: 超乎常人的力度 | AH25: 左右横跳 | AI25: 你从来就不知道什么叫生病 | AJ25: 就是个天才 | AK25: 身边的一切风吹草动都逃不出您的敏锐的目光 | AL25: 您不经意间的一举一动都有可能吸引着其他人
A26: 26 | B26: =IF(法术书I!W33="","",法术书I!W33) | C26: =IFERROR(VLOOKUP(B26,列表!$B:$B,1,FALSE),"QuQ") -> QuQ | D26: =IFERROR(VLOOKUP(C26,列表!$B:$T,17,FALSE),"") | E26: 26 | F26: =IF(法术书II!W33="","",法术书II!W33) | G26: =IFERROR(VLOOKUP(F26,列表!$B:$B,1,FALSE),"QuQ") -> QuQ | H26: =IFERROR(VLOOKUP(G26,列表!$B:$T,17,FALSE),"") | I26: 26 | J26: =IF(法术书III!W33="","",法术书III!W33) | K26: =IFERROR(VLOOKUP(J26,列表!$B:$B,1,FALSE),"QuQ") -> QuQ | L26: =IFERROR(VLOOKUP(K26,列表!$B:$T,17,FALSE),"") | O26: 900 | P26: 3 | R26: 装备同调数量 | T26: 双腿 | U26: 强酸 | X26: 链枷 | Y26: 10gp | Z26: 1d8钝击 | AA26: 2lb | AB26: - | AC26: 力量 | AF26: 17
A27: 27 | B27: =IF(法术书I!W34="","",法术书I!W34) | C27: =IFERROR(VLOOKUP(B27,列表!$B:$B,1,FALSE),"QuQ") -> QuQ | D27: =IFERROR(VLOOKUP(C27,列表!$B:$T,17,FALSE),"") | E27: 27 | F27: =IF(法术书II!W34="","",法术书II!W34) | G27: =IFERROR(VLOOKUP(F27,列表!$B:$B,1,FALSE),"QuQ") -> QuQ | H27: =IFERROR(VLOOKUP(G27,列表!$B:$T,17,FALSE),"") | I27: 27 | J27: =IF(法术书III!W34="","",法术书III!W34) | K27: =IFERROR(VLOOKUP(J27,列表!$B:$B,1,FALSE),"QuQ") -> QuQ | L27: =IFERROR(VLOOKUP(K27,列表!$B:$T,17,FALSE),"") | O27: =O26*P26 -> 2700 | P27: 4 | R27: FALSE | T27: 左手 | X27: 大砍刀 | Y27: 20gp | Z27: 1d10挥砍 | AA27: 6lb | AB27: 重型，触及，双手 | AC27: 力量 | AF27: 18 | AG27: 达到人类极限力量 | AH27: 超越人类的敏捷 | AI27: 生命力旺盛，被人打趴数次还可以站起来继续的那种 | AJ27: 睿智的目光 | AK27: 这个世界上的一切联系都可以被您所感知 | AL27: 请注意你的其他属性，因为你很容易被犯罪
A28: 28 | B28: =IF(法术书I!W35="","",法术书I!W35) | C28: =IFERROR(VLOOKUP(B28,列表!$B:$B,1,FALSE),"QuQ") -> QuQ | D28: =IFERROR(VLOOKUP(C28,列表!$B:$T,17,FALSE),"") | E28: 28 | F28: =IF(法术书II!W35="","",法术书II!W35) | G28: =IFERROR(VLOOKUP(F28,列表!$B:$B,1,FALSE),"QuQ") -> QuQ | H28: =IFERROR(VLOOKUP(G28,列表!$B:$T,17,FALSE),"") | I28: 28 | J28: =IF(法术书III!W35="","",法术书III!W35) | K28: =IFERROR(VLOOKUP(J28,列表!$B:$B,1,FALSE),"QuQ") -> QuQ | L28: =IFERROR(VLOOKUP(K28,列表!$B:$T,17,FALSE),"") | O28: 6500 | P28: 5 | R28: FALSE | T28: 右手 | X28: 巨斧 | Y28: 30gp | Z28: 1d12挥砍 | AA28: 7lb | AB28: 重型，双手 | AC28: 力量 | AE28: 7 | AF28: 19 | AG28: 超越人类极限的力量 | AH28: 你跑步的样子像香港记者 | AI28: 天生的肉盾 | AJ28: 超凡的智慧 | AK28: 你开始注意到一些本来不该是人类所注意的东西了 | AL28: 红颜祸水指的就是你
A29: 29 | B29: =IF(法术书I!W36="","",法术书I!W36) | C29: =IFERROR(VLOOKUP(B29,列表!$B:$B,1,FALSE),"QuQ") -> QuQ | D29: =IFERROR(VLOOKUP(C29,列表!$B:$T,17,FALSE),"") | E29: 29 | F29: =IF(法术书II!W36="","",法术书II!W36) | G29: =IFERROR(VLOOKUP(F29,列表!$B:$B,1,FALSE),"QuQ") -> QuQ | H29: =IFERROR(VLOOKUP(G29,列表!$B:$T,17,FALSE),"") | I29: 29 | J29: =IF(法术书III!W36="","",法术书III!W36) | K29: =IFERROR(VLOOKUP(J29,列表!$B:$B,1,FALSE),"QuQ") -> QuQ | L29: =IFERROR(VLOOKUP(K29,列表!$B:$T,17,FALSE),"") | O29: 14000 | P29: 6 | R29: FALSE | T29: 双手 | X29: 巨剑 | Y29: 50gp | Z29: 2d6挥砍 | AA29: 6lb | AB29: 重型，双手 | AC29: 力量 | AE29: 8 | AF29: 20 | AG29: 熊的力量！ | AH29: 无与伦比的运动神经 | AI29: 或许有复数血条 | AJ29: 你可以改变世界 | AK29: 所有的谎言在你面前无所遁形 | AL29: 沉鱼落雁，闭月羞花
A30: 30 | B30: =IF(法术书I!W37="","",法术书I!W37) | C30: =IFERROR(VLOOKUP(B30,列表!$B:$B,1,FALSE),"QuQ") -> QuQ | D30: =IFERROR(VLOOKUP(C30,列表!$B:$T,17,FALSE),"") | E30: 30 | F30: =IF(法术书II!W37="","",法术书II!W37) | G30: =IFERROR(VLOOKUP(F30,列表!$B:$B,1,FALSE),"QuQ") -> QuQ | H30: =IFERROR(VLOOKUP(G30,列表!$B:$T,17,FALSE),"") | I30: 30 | J30: =IF(法术书III!W37="","",法术书III!W37) | K30: =IFERROR(VLOOKUP(J30,列表!$B:$B,1,FALSE),"QuQ") -> QuQ | L30: =IFERROR(VLOOKUP(K30,列表!$B:$T,17,FALSE),"") | O30: 23000 | P30: 7 | R30: FALSE | T30: 左臂 | X30: 戟 | Y30: 20gp | Z30: 1d10挥砍 | AA30: 6lb | AB30: 重型，触及，双手 | AC30: 力量 | AF30: 21 | AG30: 怪物之力 | AH30: 跑得比香港记者还快 | AI30: 大概只有天灾才杀死这种人 | AJ30: 或许是参透法则之人 | AK30: 路过坟墓你就能看见鬼魂，经过战场你就能听见哀号 | AL30: 您的敌人也可能会倾向于你
A31: 31 | B31: =IF(法术书I!W38="","",法术书I!W38) | C31: =IFERROR(VLOOKUP(B31,列表!$B:$B,1,FALSE),"QuQ") -> QuQ | D31: =IFERROR(VLOOKUP(C31,列表!$B:$T,17,FALSE),"") | E31: 31 | F31: =IF(法术书II!W38="","",法术书II!W38) | G31: =IFERROR(VLOOKUP(F31,列表!$B:$B,1,FALSE),"QuQ") -> QuQ | H31: =IFERROR(VLOOKUP(G31,列表!$B:$T,17,FALSE),"") | I31: 31 | J31: =IF(法术书III!W38="","",法术书III!W38) | K31: =IFERROR(VLOOKUP(J31,列表!$B:$B,1,FALSE),"QuQ") -> QuQ | L31: =IFERROR(VLOOKUP(K31,列表!$B:$T,17,FALSE),"") | O31: 34000 | P31: 8 | R31: FALSE | T31: 右臂 | X31: 骑枪 | Y31: 10gp | Z31: 1d12穿刺 | AA31: 6lb | AB31: 触及，特殊 | AC31: 力量 | AF31: 22 | AG31: 吃饭的时候经常不小心捏碎十几个盘子 | AH31: 只要你想要，世界上没什么你弄不到东西 | AI31: 被杀不一定会死 | AJ31: 用睿智这个词来形容你都已经是一种侮辱了 | AK31: 敌人的隐形和变形对你来说毫无意义 | AL31: 你很少动刀动枪，因为只要有你的存在就能化解绝大多数的纷争
A32: 32 | B32: =IF(法术书I!W39="","",法术书I!W39) | C32: =IFERROR(VLOOKUP(B32,列表!$B:$B,1,FALSE),"QuQ") -> QuQ | D32: =IFERROR(VLOOKUP(C32,列表!$B:$T,17,FALSE),"") | E32: 32 | F32: =IF(法术书II!W39="","",法术书II!W39) | G32: =IFERROR(VLOOKUP(F32,列表!$B:$B,1,FALSE),"QuQ") -> QuQ | H32: =IFERROR(VLOOKUP(G32,列表!$B:$T,17,FALSE),"") | I32: 32 | J32: =IF(法术书III!W39="","",法术书III!W39) | K32: =IFERROR(VLOOKUP(J32,列表!$B:$B,1,FALSE),"QuQ") -> QuQ | L32: =IFERROR(VLOOKUP(K32,列表!$B:$T,17,FALSE),"") | O32: 48000 | P32: 9 | R32: FALSE | T32: 双臂 | X32: 长剑 | Y32: 15gp | Z32: 1d8挥砍 | AA32: 3lb | AB32: 多用途(1d10） | AC32: 力量 | AF32: 23 | AG32: 经常不小心将别人摸成骨折，当地的骨科医生都很喜欢你 | AH32: 几乎没有东西有足够的速度能伤害到你 | AI32: 最受欢迎的肉盾 | AJ32: 你一眼就能看清事物的本质，再没有任何事物能够引起你的好奇 | AK32: 任何生物在你眼中他的一生命运都历历在目，任何非生物的历史你也一目了然 | AL32: 只有意志最坚定的人才能直视你
A33: 33 | B33: =IF(法术书I!W40="","",法术书I!W40) | C33: =IFERROR(VLOOKUP(B33,列表!$B:$B,1,FALSE),"QuQ") -> QuQ | D33: =IFERROR(VLOOKUP(C33,列表!$B:$T,17,FALSE),"") | E33: 33 | F33: =IF(法术书II!W40="","",法术书II!W40) | G33: =IFERROR(VLOOKUP(F33,列表!$B:$B,1,FALSE),"QuQ") -> QuQ | H33: =IFERROR(VLOOKUP(G33,列表!$B:$T,17,FALSE),"") | I33: 33 | J33: =IF(法术书III!W40="","",法术书III!W40) | K33: =IFERROR(VLOOKUP(J33,列表!$B:$B,1,FALSE),"QuQ") -> QuQ | L33: =IFERROR(VLOOKUP(K33,列表!$B:$T,17,FALSE),"") | O33: 64000 | P33: 10 | R33: FALSE | T33: 全身 | X33: 巨锤 | Y33: 10gp | Z33: 2d6钝击 | AA33: 10lb | AB33: 重型，双手 | AC33: 力量 | AF33: 24 | AG33: 你付账的时候从口袋里掏出来的，往往不是金币而是被巨大的力量捏成一坨的金块 | AH33: 战斗的时候，敌人最头痛的就是你，因为他根本砍不到你 | AI33: 强壮的体质使你在冒险团队中所向无敌 | AJ33: 世间的一切在你眼中都索然无味 | AK33: 世界上所有的神祗都在要求你做他们的使徒 | AL33: 你的一个眼神、一个动作，都可能轻易的左右其他人的思想，决定国家的存亡
A34: 34 | B34: =IF(法术书I!W41="","",法术书I!W41) | C34: =IFERROR(VLOOKUP(B34,列表!$B:$B,1,FALSE),"QuQ") -> QuQ | D34: =IFERROR(VLOOKUP(C34,列表!$B:$T,17,FALSE),"") | E34: 34 | F34: =IF(法术书II!W41="","",法术书II!W41) | G34: =IFERROR(VLOOKUP(F34,列表!$B:$B,1,FALSE),"QuQ") -> QuQ | H34: =IFERROR(VLOOKUP(G34,列表!$B:$T,17,FALSE),"") | I34: 34 | J34: =IF(法术书III!W41="","",法术书III!W41) | K34: =IFERROR(VLOOKUP(J34,列表!$B:$B,1,FALSE),"QuQ") -> QuQ | L34: =IFERROR(VLOOKUP(K34,列表!$B:$T,17,FALSE),"") | O34: 85000 | P34: 11 | R34: FALSE | X34: 钉头锤 | Y34: 15gp | Z34: 1d8穿刺 | AA34: 4lb | AB34: - | AC34: 力量 | AF34: 25 | AG34: 因为你的存在，你所居住的小镇已经很多年没有买过起重机了 | AH34: 你从别人身边走过，别人会以为只是一阵风吹过 | AI34: 传奇肉盾 | AJ34: 完全可以去客串半神巫妖 | AK34: 你能够直接倾听神祗的话语与神交流，你就是真正的神使 | AL34: 天上的众神为了争夺你打的不可开交，深渊中的恶魔因为你的存在而不愿破坏世界
A35: 35 | B35: =IF(法术书I!W42="","",法术书I!W42) | C35: =IFERROR(VLOOKUP(B35,列表!$B:$B,1,FALSE),"QuQ") -> QuQ | D35: =IFERROR(VLOOKUP(C35,列表!$B:$T,17,FALSE),"") | E35: 35 | F35: =IF(法术书II!W42="","",法术书II!W42) | G35: =IFERROR(VLOOKUP(F35,列表!$B:$B,1,FALSE),"QuQ") -> QuQ | H35: =IFERROR(VLOOKUP(G35,列表!$B:$T,17,FALSE),"") | I35: 35 | J35: =IF(法术书III!W42="","",法术书III!W42) | K35: =IFERROR(VLOOKUP(J35,列表!$B:$B,1,FALSE),"QuQ") -> QuQ | L35: =IFERROR(VLOOKUP(K35,列表!$B:$T,17,FALSE),"") | O35: 100000 | P35: 12 | R35: FALSE | T35: - | X35: 长矛 | Y35: 5gp | Z35: 1d10穿刺 | AA35: 18lb | AB35: 重型，触及，双手 | AC35: 力量
A36: 36 | B36: =IF(法术书I!W43="","",法术书I!W43) | C36: =IFERROR(VLOOKUP(B36,列表!$B:$B,1,FALSE),"QuQ") -> QuQ | D36: =IFERROR(VLOOKUP(C36,列表!$B:$T,17,FALSE),"") | E36: 36 | F36: =IF(法术书II!W43="","",法术书II!W43) | G36: =IFERROR(VLOOKUP(F36,列表!$B:$B,1,FALSE),"QuQ") -> QuQ | H36: =IFERROR(VLOOKUP(G36,列表!$B:$T,17,FALSE),"") | I36: 36 | J36: =IF(法术书III!W43="","",法术书III!W43) | K36: =IFERROR(VLOOKUP(J36,列表!$B:$B,1,FALSE),"QuQ") -> QuQ | L36: =IFERROR(VLOOKUP(K36,列表!$B:$T,17,FALSE),"") | O36: 120000 | P36: 13 | R36: FALSE | T36: 轻型 | V36: =主要!$I$13 -> 0 | X36: 刺剑 | Y36: 25gp | Z36: 1d8穿刺 | AA36: 2lb | AB36: 灵巧 | AC36: =IF(主要!$I$11>=主要!$I$13,"力量","敏捷") -> 力量 | AG36: 力量 | AH36: 敏捷 | AI36: 体质 | AJ36: 智力 | AK36: 感知 | AL36: 魅力
A37: 37 | B37: =IF(法术书I!W44="","",法术书I!W44) | C37: =IFERROR(VLOOKUP(B37,列表!$B:$B,1,FALSE),"QuQ") -> QuQ | D37: =IFERROR(VLOOKUP(C37,列表!$B:$T,17,FALSE),"") | E37: 37 | F37: =IF(法术书II!W44="","",法术书II!W44) | G37: =IFERROR(VLOOKUP(F37,列表!$B:$B,1,FALSE),"QuQ") -> QuQ | H37: =IFERROR(VLOOKUP(G37,列表!$B:$T,17,FALSE),"") | I37: 37 | J37: =IF(法术书III!W44="","",法术书III!W44) | K37: =IFERROR(VLOOKUP(J37,列表!$B:$B,1,FALSE),"QuQ") -> QuQ | L37: =IFERROR(VLOOKUP(K37,列表!$B:$T,17,FALSE),"") | O37: 140000 | P37: 14 | R37: FALSE | T37: 中型 | U37: 2 | V37: =IF(主要!$I$13>=U37,U37,主要!$I$13) -> 0 | X37: 弯刀 | Y37: 25gp | Z37: 1d6挥砍 | AA37: 3lb | AB37: 灵巧，轻 | AC37: =IF(主要!$I$11>=主要!$I$13,"力量","敏捷") -> 力量 | AG37: =IF(主要!F11<>"",主要!F11,"") -> 10 | AH37: =IF(主要!F13<>"",主要!F13,"") -> 10 | AI37: =IF(主要!F15<>"",主要!F15,"") -> 10 | AJ37: =IF(主要!F17<>"",主要!F17,"") -> 10 | AK37: =IF(主要!F19<>"",主要!F19,"") -> 10 | AL37: =IF(主要!F21<>"",主要!F21,"") -> 10
A38: 38 | B38: =IF(法术书I!W45="","",法术书I!W45) | C38: =IFERROR(VLOOKUP(B38,列表!$B:$B,1,FALSE),"QuQ") -> QuQ | D38: =IFERROR(VLOOKUP(C38,列表!$B:$T,17,FALSE),"") | E38: 38 | F38: =IF(法术书II!W45="","",法术书II!W45) | G38: =IFERROR(VLOOKUP(F38,列表!$B:$B,1,FALSE),"QuQ") -> QuQ | H38: =IFERROR(VLOOKUP(G38,列表!$B:$T,17,FALSE),"") | I38: 38 | J38: =IF(法术书III!W45="","",法术书III!W45) | K38: =IFERROR(VLOOKUP(J38,列表!$B:$B,1,FALSE),"QuQ") -> QuQ | L38: =IFERROR(VLOOKUP(K38,列表!$B:$T,17,FALSE),"") | O38: 165000 | P38: 15 | R38: FALSE | T38: 重型 | U38: 0 | V38: =IF(主要!$I$13<0,0,IF(主要!$I$13>=U38,U38,主要!$I$13)) -> 0 | X38: 短剑 | Y38: 10gp | Z38: 1d6穿刺 | AA38: 2lb | AB38: 灵巧，轻 | AC38: =IF(主要!$I$11>=主要!$I$13,"力量","敏捷") -> 力量 | AG38: =IF(AG37="","",IF(AG37<=1,AG10,IF(AG37=2,AG11,IF(AG37=3,AG12,IF(AG37=4,AG13,IF(AG37=5,AG14,IF(AG37=6,AG15,IF(AG37=7,AG16,IF(AG37=8,AG17,IF(AG37=9,AG18,IF(AG37=10,AG19,IF(AG37=11,AG20,IF(AG37=12,AG21,IF(AG37<=14,AG22,IF(AG37<=17,AG25,IF(AG37=18,AG27,IF(AG37=19,AG28,IF(AG37=20,AG29,IF(AG37=21,AG30,IF(AG37=22,AG31,IF(AG37=23,AG32,IF(AG37=24,AG33,IF(AG37>=25,AG34))))))))))))))))))))))) -> 有正常人的力量 | AH38: =IF(AH37="","",IF(AH37<=1,AH10,IF(AH37=2,AH11,IF(AH37=3,AH12,IF(AH37=4,AH13,IF(AH37=5,AH14,IF(AH37=6,AH15,IF(AH37=7,AH16,IF(AH37=8,AH17,IF(AH37=9,AH18,IF(AH37=10,AH19,IF(AH37=11,AH20,IF(AH37=12,AH21,IF(AH37<=14,AH22,IF(AH37<=17,AH25,IF(AH37=18,AH27,IF(AH37=19,AH28,IF(AH37=20,AH29,IF(AH37=21,AH30,IF(AH37=22,AH31,IF(AH37=23,AH32,IF(AH37=24,AH33,IF(AH37>=25,AH34))))))))))))))))))))))) -> 普通人的水准 | AI38: =IF(AI37="","",IF(AI37<=1,AI10,IF(AI37=2,AI11,IF(AI37=3,AI12,IF(AI37=4,AI13,IF(AI37=5,AI14,IF(AI37=6,AI15,IF(AI37=7,AI16,IF(AI37=8,AI17,IF(AI37=9,AI18,IF(AI37=10,AI19,IF(AI37=11,AI20,IF(AI37=12,AI21,IF(AI37<=14,AI22,IF(AI37<=17,AI25,IF(AI37=18,AI27,IF(AI37=19,AI28,IF(AI37=20,AI29,IF(AI37=21,AI30,IF(AI37=22,AI31,IF(AI37=23,AI32,IF(AI37=24,AI33,IF(AI37>=25,AI34))))))))))))))))))))))) -> 正常人的体质 | AJ38: =IF(AJ37="","",IF(AJ37<=1,AJ10,IF(AJ37=2,AJ11,IF(AJ37=3,AJ12,IF(AJ37=4,AJ13,IF(AJ37=5,AJ14,IF(AJ37=6,AJ15,IF(AJ37=7,AJ16,IF(AJ37=8,AJ17,IF(AJ37=9,AJ18,IF(AJ37=10,AJ19,IF(AJ37=11,AJ20,IF(AJ37=12,AJ21,IF(AJ37<=14,AJ22,IF(AJ37<=17,AJ25,IF(AJ37=18,AJ27,IF(AJ37=19,AJ28,IF(AJ37=20,AJ29,IF(AJ37=21,AJ30,IF(AJ37=22,AJ31,IF(AJ37=23,AJ32,IF(AJ37=24,AJ33,IF(AJ37>=25,AJ34))))))))))))))))))))))) -> 正常人的智力 | AK38: =IF(AK37="","",IF(AK37<=1,AK10,IF(AK37=2,AK11,IF(AK37=3,AK12,IF(AK37=4,AK13,IF(AK37=5,AK14,IF(AK37=6,AK15,IF(AK37=7,AK16,IF(AK37=8,AK17,IF(AK37=9,AK18,IF(AK37=10,AK19,IF(AK37=11,AK20,IF(AK37=12,AK21,IF(AK37<=14,AK22,IF(AK37<=17,AK25,IF(AK37=18,AK27,IF(AK37=19,AK28,IF(AK37=20,AK29,IF(AK37=21,AK30,IF(AK37=22,AK31,IF(AK37=23,AK32,IF(AK37=24,AK33,IF(AK37>=25,AK34))))))))))))))))))))))) -> 你醒啦，你很正常 | AL38: =IF(AL37="","",IF(AL37<=1,AL10,IF(AL37=2,AL11,IF(AL37=3,AL12,IF(AL37=4,AL13,IF(AL37=5,AL14,IF(AL37=6,AL15,IF(AL37=7,AL16,IF(AL37=8,AL17,IF(AL37=9,AL18,IF(AL37=10,AL19,IF(AL37=11,AL20,IF(AL37=12,AL21,IF(AL37<=14,AL22,IF(AL37<=17,AL25,IF(AL37=18,AL27,IF(AL37=19,AL28,IF(AL37=20,AL29,IF(AL37=21,AL30,IF(AL37=22,AL31,IF(AL37=23,AL32,IF(AL37=24,AL33,IF(AL37>=25,AL34))))))))))))))))))))))) -> 讨价还价的能力不错
A39: 39 | B39: =IF(法术书I!W46="","",法术书I!W46) | C39: =IFERROR(VLOOKUP(B39,列表!$B:$B,1,FALSE),"QuQ") -> QuQ | D39: =IFERROR(VLOOKUP(C39,列表!$B:$T,17,FALSE),"") | E39: 39 | F39: =IF(法术书II!W46="","",法术书II!W46) | G39: =IFERROR(VLOOKUP(F39,列表!$B:$B,1,FALSE),"QuQ") -> QuQ | H39: =IFERROR(VLOOKUP(G39,列表!$B:$T,17,FALSE),"") | I39: 39 | J39: =IF(法术书III!W46="","",法术书III!W46) | K39: =IFERROR(VLOOKUP(J39,列表!$B:$B,1,FALSE),"QuQ") -> QuQ | L39: =IFERROR(VLOOKUP(K39,列表!$B:$T,17,FALSE),"") | O39: 195000 | P39: 16 | R39: FALSE | T39: 盾牌 | V39: ？ | X39: 三叉戟 | Y39: 5gp | Z39: 1d6穿刺 | AA39: 4lb | AB39: 投掷(射程20/60)，多用途(1d8) | AC39: 力量
A40: 40 | B40: =IF(法术书I!W47="","",法术书I!W47) | C40: =IFERROR(VLOOKUP(B40,列表!$B:$B,1,FALSE),"QuQ") -> QuQ | D40: =IFERROR(VLOOKUP(C40,列表!$B:$T,17,FALSE),"") | E40: 40 | F40: =IF(法术书II!W47="","",法术书II!W47) | G40: =IFERROR(VLOOKUP(F40,列表!$B:$B,1,FALSE),"QuQ") -> QuQ | H40: =IFERROR(VLOOKUP(G40,列表!$B:$T,17,FALSE),"") | I40: 40 | J40: =IF(法术书III!W47="","",法术书III!W47) | K40: =IFERROR(VLOOKUP(J40,列表!$B:$B,1,FALSE),"QuQ") -> QuQ | L40: =IFERROR(VLOOKUP(K40,列表!$B:$T,17,FALSE),"") | O40: 225000 | P40: 17 | R40: FALSE | X40: 战镐 | Y40: 5gp | Z40: 1d8穿刺 | AA40: 2 | AB40: - | AC40: 力量 | AG40: 运动 | AH40: =VLOOKUP($AG40,主要!C:J,7,FALSE) -> 0
...

Sheet 背包
A1: 背包 Inventory
B3: 背包1 | V3: =SUM(DB!A2:A22) -> 0 | Y3: 背包2 | AS3: =SUM(DB!B2:B22) -> 0
B4: 名称 | I4: 描述 | S4: lb | V4: 数量 | Y4: 名称 | AF4: 描述 | AP4: lb | AS4: 数量
U5: × | AR5: ×
U6: × | AR6: ×
U7: × | AR7: ×
U8: × | AR8: ×
U9: × | AR9: ×
U10: × | AR10: ×
U11: × | AR11: ×
U12: × | AR12: ×
U13: × | AR13: ×
U14: × | AR14: ×
U16: × | AR16: ×
U17: × | AR17: ×
... U25: × | AR25: ×
B27: 背包3（次元袋） | V27: 无效 | Y27: 背包4（次元袋） | AS27: 无效
B28: 名称 | I28: 描述 | S28: lb | V28: 数量 | Y28: 名称 | AF28: 描述 | AP28: lb | AS28: 数量
U29: × | AR29: ×
U30: × | AR30: ×
U31: × | AR31: ×
U32: × | AR32: ×
U33: × | AR33: ×
U34: × | AR34: ×
U35: × | AR35: ×
U36: × | AR36: ×
U37: × | AR37: ×
U38: × | AR38: ×
U40: × | AR40: ×
U41: × | AR41: ×
... U82: × | AR82: ×
B84: 次元袋负重（实际） | J84: 15 | M84: 次元袋负重（收纳） | U84: =SUM(DB!C2:C55) -> 0 | Y84: 次元袋负重（实际） | AG84: 15 | AJ84: 次元袋负重（收纳） | AR84: =SUM(DB!D2:D55) -> 0
B86: 玩家笔记1 | Y86: 玩家笔记2
B112: 个人据点储物箱 | Y112: 个人据点财产 | AH112: 个人财产收入
C113: 物品名称 | I113: 物品描述 | V113: 数量 | Y113: 币种 | AA113: 数量 | AH113: 币种 | AJ113: 来源
B114: 1 | Y114: PP | AH114: PP
B115: 2 | Y115: EP | AH115: EP
B116: 3 | Y116: GP | AH116: GP
B117: 4 | Y117: SP | AH117: SP
B118: 5 | Y118: CP | AH118: CP
...

Sheet 法术书I
C3: =IFERROR(IF(AA5<>"",AA5,(IF(W5=VLOOKUP(W5,列表!$B$2:$L$557,11,FALSE),W5,""))),"")
T4: 书页标签
U5: =IF(W5="","","Lv") | W5: =IFERROR(VLOOKUP(法术书目录!$O$1,法术书目录!$A:$C,2,FALSE),"空白标签") | X5: 优先读取 | Y5: =IF(AA5="","","Lv")
U6: =IFERROR(VLOOKUP((VLOOKUP(W5,列表!$B:$T,13,FALSE)),法术书目录!$Q$1:$R$10,2,FALSE),"") | Y6: =IFERROR(VLOOKUP((VLOOKUP(AA5,列表!$B:$T,13,FALSE)),法术书目录!$Q$1:$R$10,2,FALSE),"")
T7: 目录
C8: =IFERROR(VLOOKUP(C3,列表!$B:$T,12,FALSE),"") | O8: =IFERROR(VLOOKUP(C3,列表!$B:$T,2,FALSE),"") | T8: =IF(法术书目录!C1<>"QuQ",AC8,"") | U8: =IFERROR(VLOOKUP((VLOOKUP(W8,列表!$B:$T,13,FALSE)),法术书目录!$Q$1:$R$10,2,FALSE),"") | V8: =法术书目录!D1 | X8: =IF(法术书目录!C46<>"QuQ",AD8,"") | Y8: =IFERROR(VLOOKUP((VLOOKUP(AA8,列表!$B:$T,13,FALSE)),法术书目录!$Q$1:$R$10,2,FALSE),"") | Z8: =法术书目录!D46 | AC8: 1 | AD8: 46
C9: =IF(E9<>"","适用职业：","") | E9: =IFERROR(VLOOKUP(C3,列表!$B:$T,3,FALSE),"") | K9: =IF(M9<>"","等级：","") | M9: =IFERROR(VLOOKUP(C3,列表!$B:$T,13,FALSE),"") | O9: =IF(Q9<>"","系别：","") | Q9: =IFERROR(VLOOKUP(C3,列表!$B:$T,14,FALSE),"") | T9: =IF(法术书目录!C2<>"QuQ",AC9,"") | U9: =IFERROR(VLOOKUP((VLOOKUP(W9,列表!$B:$T,13,FALSE)),法术书目录!$Q$1:$R$10,2,FALSE),"") | V9: =法术书目录!D2 | X9: =IF(法术书目录!C47<>"QuQ",AD9,"") | Y9: =IFERROR(VLOOKUP((VLOOKUP(AA9,列表!$B:$T,13,FALSE)),法术书目录!$Q$1:$R$10,2,FALSE),"") | Z9: =法术书目录!D47 | AC9: 2 | AD9: 47
T10: =IF(法术书目录!C3<>"QuQ",AC10,"") | U10: =IFERROR(VLOOKUP((VLOOKUP(W10,列表!$B:$T,13,FALSE)),法术书目录!$Q$1:$R$10,2,FALSE),"") | V10: =法术书目录!D3 | X10: =IF(法术书目录!C48<>"QuQ",AD10,"") | Y10: =IFERROR(VLOOKUP((VLOOKUP(AA10,列表!$B:$T,13,FALSE)),法术书目录!$Q$1:$R$10,2,FALSE),"") | Z10: =法术书目录!D48 | AC10: 3 | AD10: 48
C11: =IF(E11<>"","施法时间：","") | E11: =IFERROR(VLOOKUP(C3,列表!$B:$T,5,FALSE),"") | K11: =IF(M11<>"","施法距离：","") | M11: =IFERROR(VLOOKUP(C3,列表!$B:$T,6,FALSE),"") | T11: =IF(法术书目录!C4<>"QuQ",AC11,"") | U11: =IFERROR(VLOOKUP((VLOOKUP(W11,列表!$B:$T,13,FALSE)),法术书目录!$Q$1:$R$10,2,FALSE),"") | V11: =法术书目录!D4 | X11: =IF(法术书目录!C49<>"QuQ",AD11,"") | Y11: =IFERROR(VLOOKUP((VLOOKUP(AA11,列表!$B:$T,13,FALSE)),法术书目录!$Q$1:$R$10,2,FALSE),"") | Z11: =法术书目录!D49 | AC11: 4 | AD11: 49
T12: =IF(法术书目录!C5<>"QuQ",AC12,"") | U12: =IFERROR(VLOOKUP((VLOOKUP(W12,列表!$B:$T,13,FALSE)),法术书目录!$Q$1:$R$10,2,FALSE),"") | V12: =法术书目录!D5 | X12: =IF(法术书目录!C50<>"QuQ",AD12,"") | Y12: =IFERROR(VLOOKUP((VLOOKUP(AA12,列表!$B:$T,13,FALSE)),法术书目录!$Q$1:$R$10,2,FALSE),"") | Z12: =法术书目录!D50 | AC12: 5 | AD12: 50
C13: =IF(E13<>"","法术成分：","") | E13: =IFERROR(VLOOKUP(C3,列表!$B:$T,15,FALSE),"") | F13: =IF(H13<>"","法术材料：","") | H13: =IFERROR(IF(VLOOKUP(C3,列表!$B:$T,16,FALSE)=0,"",VLOOKUP(C3,列表!$B:$T,16,FALSE)),"") | T13: =IF(法术书目录!C6<>"QuQ",AC13,"") | U13: =IFERROR(VLOOKUP((VLOOKUP(W13,列表!$B:$T,13,FALSE)),法术书目录!$Q$1:$R$10,2,FALSE),"") | V13: =法术书目录!D6 | X13: =IF(法术书目录!C51<>"QuQ",AD13,"") | Y13: =IFERROR(VLOOKUP((VLOOKUP(AA13,列表!$B:$T,13,FALSE)),法术书目录!$Q$1:$R$10,2,FALSE),"") | Z13: =法术书目录!D51 | AC13: 6 | AD13: 51
T14: =IF(法术书目录!C7<>"QuQ",AC14,"") | U14: =IFERROR(VLOOKUP((VLOOKUP(W14,列表!$B:$T,13,FALSE)),法术书目录!$Q$1:$R$10,2,FALSE),"") | V14: =法术书目录!D7 | X14: =IF(法术书目录!C52<>"QuQ",AD14,"") | Y14: =IFERROR(VLOOKUP((VLOOKUP(AA14,列表!$B:$T,13,FALSE)),法术书目录!$Q$1:$R$10,2,FALSE),"") | Z14: =法术书目录!D52 | AC14: 7 | AD14: 52
T15: =IF(法术书目录!C8<>"QuQ",AC15,"") | U15: =IFERROR(VLOOKUP((VLOOKUP(W15,列表!$B:$T,13,FALSE)),法术书目录!$Q$1:$R$10,2,FALSE),"") | V15: =法术书目录!D8 | X15: =IF(法术书目录!C53<>"QuQ",AD15,"") | Y15: =IFERROR(VLOOKUP((VLOOKUP(AA15,列表!$B:$T,13,FALSE)),法术书目录!$Q$1:$R$10,2,FALSE),"") | Z15: =法术书目录!D53 | AC15: 8 | AD15: 53
T16: =IF(法术书目录!C9<>"QuQ",AC16,"") | U16: =IFERROR(VLOOKUP((VLOOKUP(W16,列表!$B:$T,13,FALSE)),法术书目录!$Q$1:$R$10,2,FALSE),"") | V16: =法术书目录!D9 | X16: =IF(法术书目录!C54<>"QuQ",AD16,"") | Y16: =IFERROR(VLOOKUP((VLOOKUP(AA16,列表!$B:$T,13,FALSE)),法术书目录!$Q$1:$R$10,2,FALSE),"") | Z16: =法术书目录!D54 | AC16: 9 | AD16: 54
T17: =IF(法术书目录!C10<>"QuQ",AC17,"") | U17: =IFERROR(VLOOKUP((VLOOKUP(W17,列表!$B:$T,13,FALSE)),法术书目录!$Q$1:$R$10,2,FALSE),"") | V17: =法术书目录!D10 | X17: =IF(法术书目录!C55<>"QuQ",AD17,"") | Y17: =IFERROR(VLOOKUP((VLOOKUP(AA17,列表!$B:$T,13,FALSE)),法术书目录!$Q$1:$R$10,2,FALSE),"") | Z17: =法术书目录!D55 | AC17: 10 | AD17: 55
T18: =IF(法术书目录!C11<>"QuQ",AC18,"") | U18: =IFERROR(VLOOKUP((VLOOKUP(W18,列表!$B:$T,13,FALSE)),法术书目录!$Q$1:$R$10,2,FALSE),"") | V18: =法术书目录!D11 | X18: =IF(法术书目录!C56<>"QuQ",AD18,"") | Y18: =IFERROR(VLOOKUP((VLOOKUP(AA18,列表!$B:$T,13,FALSE)),法术书目录!$Q$1:$R$10,2,FALSE),"") | Z18: =法术书目录!D56 | AC18: 11 | AD18: 56
C19: =IF(E19<>"","持续时间：","") | E19: =IFERROR(VLOOKUP(C3,列表!$B:$T,8,FALSE),"") | T19: =IF(法术书目录!C12<>"QuQ",AC19,"") | U19: =IFERROR(VLOOKUP((VLOOKUP(W19,列表!$B:$T,13,FALSE)),法术书目录!$Q$1:$R$10,2,FALSE),"") | V19: =法术书目录!D12 | X19: =IF(法术书目录!C57<>"QuQ",AD19,"") | Y19: =IFERROR(VLOOKUP((VLOOKUP(AA19,列表!$B:$T,13,FALSE)),法术书目录!$Q$1:$R$10,2,FALSE),"") | Z19: =法术书目录!D57 | AC19: 12 | AD19: 57
T20: =IF(法术书目录!C13<>"QuQ",AC20,"") | U20: =IFERROR(VLOOKUP((VLOOKUP(W20,列表!$B:$T,13,FALSE)),法术书目录!$Q$1:$R$10,2,FALSE),"") | V20: =法术书目录!D13 | X20: =IF(法术书目录!C58<>"QuQ",AD20,"") | Y20: =IFERROR(VLOOKUP((VLOOKUP(AA20,列表!$B:$T,13,FALSE)),法术书目录!$Q$1:$R$10,2,FALSE),"") | Z20: =法术书目录!D58 | AC20: 13 | AD20: 58
T21: =IF(法术书目录!C14<>"QuQ",AC21,"") | U21: =IFERROR(VLOOKUP((VLOOKUP(W21,列表!$B:$T,13,FALSE)),法术书目录!$Q$1:$R$10,2,FALSE),"") | V21: =法术书目录!D14 | X21: =IF(法术书目录!C59<>"QuQ",AD21,"") | Y21: =IFERROR(VLOOKUP((VLOOKUP(AA21,列表!$B:$T,13,FALSE)),法术书目录!$Q$1:$R$10,2,FALSE),"") | Z21: =法术书目录!D59 | AC21: 14 | AD21: 59
C22: =IF(C23<>"","法术说明","") | T22: =IF(法术书目录!C15<>"QuQ",AC22,"") | U22: =IFERROR(VLOOKUP((VLOOKUP(W22,列表!$B:$T,13,FALSE)),法术书目录!$Q$1:$R$10,2,FALSE),"") | V22: =法术书目录!D15 | X22: =IF(法术书目录!C60<>"QuQ",AD22,"") | Y22: =IFERROR(VLOOKUP((VLOOKUP(AA22,列表!$B:$T,13,FALSE)),法术书目录!$Q$1:$R$10,2,FALSE),"") | Z22: =法术书目录!D60 | AC22: 15 | AD22: 60
C23: =IFERROR(VLOOKUP(C3,列表!$B:$T,9,FALSE),"") | T23: =IF(法术书目录!C16<>"QuQ",AC23,"") | U23: =IFERROR(VLOOKUP((VLOOKUP(W23,列表!$B:$T,13,FALSE)),法术书目录!$Q$1:$R$10,2,FALSE),"") | V23: =法术书目录!D16 | X23: =IF(法术书目录!C61<>"QuQ",AD23,"") | Y23: =IFERROR(VLOOKUP((VLOOKUP(AA23,列表!$B:$T,13,FALSE)),法术书目录!$Q$1:$R$10,2,FALSE),"") | Z23: =法术书目录!D61 | AC23: 16 | AD23: 61
T24: =IF(法术书目录!C17<>"QuQ",AC24,"") | U24: =IFERROR(VLOOKUP((VLOOKUP(W24,列表!$B:$T,13,FALSE)),法术书目录!$Q$1:$R$10,2,FALSE),"") | V24: =法术书目录!D17 | X24: =IF(法术书目录!C62<>"QuQ",AD24,"") | Y24: =IFERROR(VLOOKUP((VLOOKUP(AA24,列表!$B:$T,13,FALSE)),法术书目录!$Q$1:$R$10,2,FALSE),"") | Z24: =法术书目录!D62 | AC24: 17 | AD24: 62
T25: =IF(法术书目录!C18<>"QuQ",AC25,"") | U25: =IFERROR(VLOOKUP((VLOOKUP(W25,列表!$B:$T,13,FALSE)),法术书目录!$Q$1:$R$10,2,FALSE),"") | V25: =法术书目录!D18 | X25: =IF(法术书目录!C63<>"QuQ",AD25,"") | Y25: =IFERROR(VLOOKUP((VLOOKUP(AA25,列表!$B:$T,13,FALSE)),法术书目录!$Q$1:$R$10,2,FALSE),"") | Z25: =法术书目录!D63 | AC25: 18 | AD25: 63
T26: =IF(法术书目录!C19<>"QuQ",AC26,"") | U26: =IFERROR(VLOOKUP((VLOOKUP(W26,列表!$B:$T,13,FALSE)),法术书目录!$Q$1:$R$10,2,FALSE),"") | V26: =法术书目录!D19 | X26: =IF(法术书目录!C64<>"QuQ",AD26,"") | Y26: =IFERROR(VLOOKUP((VLOOKUP(AA26,列表!$B:$T,13,FALSE)),法术书目录!$Q$1:$R$10,2,FALSE),"") | Z26: =法术书目录!D64 | AC26: 19 | AD26: 64
T27: =IF(法术书目录!C20<>"QuQ",AC27,"") | U27: =IFERROR(VLOOKUP((VLOOKUP(W27,列表!$B:$T,13,FALSE)),法术书目录!$Q$1:$R$10,2,FALSE),"") | V27: =法术书目录!D20 | X27: =IF(法术书目录!C65<>"QuQ",AD27,"") | Y27: =IFERROR(VLOOKUP((VLOOKUP(AA27,列表!$B:$T,13,FALSE)),法术书目录!$Q$1:$R$10,2,FALSE),"") | Z27: =法术书目录!D65 | AC27: 20 | AD27: 65
T28: =IF(法术书目录!C21<>"QuQ",AC28,"") | U28: =IFERROR(VLOOKUP((VLOOKUP(W28,列表!$B:$T,13,FALSE)),法术书目录!$Q$1:$R$10,2,FALSE),"") | V28: =法术书目录!D21 | X28: =IF(法术书目录!C66<>"QuQ",AD28,"") | Y28: =IFERROR(VLOOKUP((VLOOKUP(AA28,列表!$B:$T,13,FALSE)),法术书目录!$Q$1:$R$10,2,FALSE),"") | Z28: =法术书目录!D66 | AC28: 21 | AD28: 66
T29: =IF(法术书目录!C22<>"QuQ",AC29,"") | U29: =IFERROR(VLOOKUP((VLOOKUP(W29,列表!$B:$T,13,FALSE)),法术书目录!$Q$1:$R$10,2,FALSE),"") | V29: =法术书目录!D22 | X29: =IF(法术书目录!C67<>"QuQ",AD29,"") | Y29: =IFERROR(VLOOKUP((VLOOKUP(AA29,列表!$B:$T,13,FALSE)),法术书目录!$Q$1:$R$10,2,FALSE),"") | Z29: =法术书目录!D67 | AC29: 22 | AD29: 67
T30: =IF(法术书目录!C23<>"QuQ",AC30,"") | U30: =IFERROR(VLOOKUP((VLOOKUP(W30,列表!$B:$T,13,FALSE)),法术书目录!$Q$1:$R$10,2,FALSE),"") | V30: =法术书目录!D23 | X30: =IF(法术书目录!C68<>"QuQ",AD30,"") | Y30: =IFERROR(VLOOKUP((VLOOKUP(AA30,列表!$B:$T,13,FALSE)),法术书目录!$Q$1:$R$10,2,FALSE),"") | Z30: =法术书目录!D68 | AC30: 23 | AD30: 68
T31: =IF(法术书目录!C24<>"QuQ",AC31,"") | U31: =IFERROR(VLOOKUP((VLOOKUP(W31,列表!$B:$T,13,FALSE)),法术书目录!$Q$1:$R$10,2,FALSE),"") | V31: =法术书目录!D24 | X31: =IF(法术书目录!C69<>"QuQ",AD31,"") | Y31: =IFERROR(VLOOKUP((VLOOKUP(AA31,列表!$B:$T,13,FALSE)),法术书目录!$Q$1:$R$10,2,FALSE),"") | Z31: =法术书目录!D69 | AC31: 24 | AD31: 69
T32: =IF(法术书目录!C25<>"QuQ",AC32,"") | U32: =IFERROR(VLOOKUP((VLOOKUP(W32,列表!$B:$T,13,FALSE)),法术书目录!$Q$1:$R$10,2,FALSE),"") | V32: =法术书目录!D25 | X32: =IF(法术书目录!C70<>"QuQ",AD32,"") | Y32: =IFERROR(VLOOKUP((VLOOKUP(AA32,列表!$B:$T,13,FALSE)),法术书目录!$Q$1:$R$10,2,FALSE),"") | Z32: =法术书目录!D70 | AC32: 25 | AD32: 70
T33: =IF(法术书目录!C26<>"QuQ",AC33,"") | U33: =IFERROR(VLOOKUP((VLOOKUP(W33,列表!$B:$T,13,FALSE)),法术书目录!$Q$1:$R$10,2,FALSE),"") | V33: =法术书目录!D26 | X33: =IF(法术书目录!C71<>"QuQ",AD33,"") | Y33: =IFERROR(VLOOKUP((VLOOKUP(AA33,列表!$B:$T,13,FALSE)),法术书目录!$Q$1:$R$10,2,FALSE),"") | Z33: =法术书目录!D71 | AC33: 26 | AD33: 71
T34: =IF(法术书目录!C27<>"QuQ",AC34,"") | U34: =IFERROR(VLOOKUP((VLOOKUP(W34,列表!$B:$T,13,FALSE)),法术书目录!$Q$1:$R$10,2,FALSE),"") | V34: =法术书目录!D27 | X34: =IF(法术书目录!C72<>"QuQ",AD34,"") | Y34: =IFERROR(VLOOKUP((VLOOKUP(AA34,列表!$B:$T,13,FALSE)),法术书目录!$Q$1:$R$10,2,FALSE),"") | Z34: =法术书目录!D72 | AC34: 27 | AD34: 72
T35: =IF(法术书目录!C28<>"QuQ",AC35,"") | U35: =IFERROR(VLOOKUP((VLOOKUP(W35,列表!$B:$T,13,FALSE)),法术书目录!$Q$1:$R$10,2,FALSE),"") | V35: =法术书目录!D28 | X35: =IF(法术书目录!C73<>"QuQ",AD35,"") | Y35: =IFERROR(VLOOKUP((VLOOKUP(AA35,列表!$B:$T,13,FALSE)),法术书目录!$Q$1:$R$10,2,FALSE),"") | Z35: =法术书目录!D73 | AC35: 28 | AD35: 73
... T52: =IF(法术书目录!C45<>"QuQ",AC52,"") | U52: =IFERROR(VLOOKUP((VLOOKUP(W52,列表!$B:$T,13,FALSE)),法术书目录!$Q$1:$R$10,2,FALSE),"") | V52: =法术书目录!D45 | X52: =IF(法术书目录!C90<>"QuQ",AD52,"") | Y52: =IFERROR(VLOOKUP((VLOOKUP(AA52,列表!$B:$T,13,FALSE)),法术书目录!$Q$1:$R$10,2,FALSE),"") | Z52: =法术书目录!D90 | AC52: 45 | AD52: 90

Sheet 法术书II
C3: =IFERROR(IF(AA5<>"",AA5,(IF(W5=VLOOKUP(W5,列表!$B$2:$L$557,11,FALSE),W5,""))),"")
T4: 书页标签
U5: =IF(W5="","","Lv") | W5: =IFERROR(VLOOKUP(法术书目录!$O$2,法术书目录!$E:$G,2,FALSE),"空白标签") | X5: 优先读取 | Y5: =IF(AA5="","","Lv")
U6: =IFERROR(VLOOKUP((VLOOKUP(W5,列表!$B:$T,13,FALSE)),法术书目录!$Q$1:$R$10,2,FALSE),"") | Y6: =IFERROR(VLOOKUP((VLOOKUP(AA5,列表!$B:$T,13,FALSE)),法术书目录!$Q$1:$R$10,2,FALSE),"")
T7: 目录
C8: =IFERROR(VLOOKUP(C3,列表!$B:$T,12,FALSE),"") | O8: =IFERROR(VLOOKUP(C3,列表!$B:$T,2,FALSE),"") | T8: =IF(法术书目录!G1<>"QuQ",AC8,"") | U8: =IFERROR(VLOOKUP((VLOOKUP(W8,列表!$B:$T,13,FALSE)),法术书目录!$Q$1:$R$10,2,FALSE),"") | V8: =法术书目录!H1 | X8: =IF(法术书目录!G46<>"QuQ",AD8,"") | Y8: =IFERROR(VLOOKUP((VLOOKUP(AA8,列表!$B:$T,13,FALSE)),法术书目录!$Q$1:$R$10,2,FALSE),"") | Z8: =法术书目录!H46 | AC8: 1 | AD8: 46
C9: =IF(E9<>"","适用职业：","") | E9: =IFERROR(VLOOKUP(C3,列表!$B:$T,3,FALSE),"") | K9: =IF(M9<>"","等级：","") | M9: =IFERROR(VLOOKUP(C3,列表!$B:$T,13,FALSE),"") | O9: =IF(Q9<>"","系别：","") | Q9: =IFERROR(VLOOKUP(C3,列表!$B:$T,14,FALSE),"") | T9: =IF(法术书目录!G2<>"QuQ",AC9,"") | U9: =IFERROR(VLOOKUP((VLOOKUP(W9,列表!$B:$T,13,FALSE)),法术书目录!$Q$1:$R$10,2,FALSE),"") | V9: =法术书目录!H2 | X9: =IF(法术书目录!G47<>"QuQ",AD9,"") | Y9: =IFERROR(VLOOKUP((VLOOKUP(AA9,列表!$B:$T,13,FALSE)),法术书目录!$Q$1:$R$10,2,FALSE),"") | Z9: =法术书目录!H47 | AC9: 2 | AD9: 47
T10: =IF(法术书目录!G3<>"QuQ",AC10,"") | U10: =IFERROR(VLOOKUP((VLOOKUP(W10,列表!$B:$T,13,FALSE)),法术书目录!$Q$1:$R$10,2,FALSE),"") | V10: =法术书目录!H3 | X10: =IF(法术书目录!G48<>"QuQ",AD10,"") | Y10: =IFERROR(VLOOKUP((VLOOKUP(AA10,列表!$B:$T,13,FALSE)),法术书目录!$Q$1:$R$10,2,FALSE),"") | Z10: =法术书目录!H48 | AC10: 3 | AD10: 48
C11: =IF(E11<>"","施法时间：","") | E11: =IFERROR(VLOOKUP(C3,列表!$B:$T,5,FALSE),"") | K11: =IF(M11<>"","施法距离：","") | M11: =IFERROR(VLOOKUP(C3,列表!$B:$T,6,FALSE),"") | T11: =IF(法术书目录!G4<>"QuQ",AC11,"") | U11: =IFERROR(VLOOKUP((VLOOKUP(W11,列表!$B:$T,13,FALSE)),法术书目录!$Q$1:$R$10,2,FALSE),"") | V11: =法术书目录!H4 | X11: =IF(法术书目录!G49<>"QuQ",AD11,"") | Y11: =IFERROR(VLOOKUP((VLOOKUP(AA11,列表!$B:$T,13,FALSE)),法术书目录!$Q$1:$R$10,2,FALSE),"") | Z11: =法术书目录!H49 | AC11: 4 | AD11: 49
T12: =IF(法术书目录!G5<>"QuQ",AC12,"") | U12: =IFERROR(VLOOKUP((VLOOKUP(W12,列表!$B:$T,13,FALSE)),法术书目录!$Q$1:$R$10,2,FALSE),"") | V12: =法术书目录!H5 | X12: =IF(法术书目录!G50<>"QuQ",AD12,"") | Y12: =IFERROR(VLOOKUP((VLOOKUP(AA12,列表!$B:$T,13,FALSE)),法术书目录!$Q$1:$R$10,2,FALSE),"") | Z12: =法术书目录!H50 | AC12: 5 | AD12: 50
C13: =IF(E13<>"","法术成分：","") | E13: =IFERROR(VLOOKUP(C3,列表!$B:$T,15,FALSE),"") | F13: =IF(H13<>"","法术材料：","") | H13: =IFERROR(IF(VLOOKUP(C3,列表!$B:$T,16,FALSE)=0,"",VLOOKUP(C3,列表!$B:$T,16,FALSE)),"") | T13: =IF(法术书目录!G6<>"QuQ",AC13,"") | U13: =IFERROR(VLOOKUP((VLOOKUP(W13,列表!$B:$T,13,FALSE)),法术书目录!$Q$1:$R$10,2,FALSE),"") | V13: =法术书目录!H6 | X13: =IF(法术书目录!G51<>"QuQ",AD13,"") | Y13: =IFERROR(VLOOKUP((VLOOKUP(AA13,列表!$B:$T,13,FALSE)),法术书目录!$Q$1:$R$10,2,FALSE),"") | Z13: =法术书目录!H51 | AC13: 6 | AD13: 51
T14: =IF(法术书目录!G7<>"QuQ",AC14,"") | U14: =IFERROR(VLOOKUP((VLOOKUP(W14,列表!$B:$T,13,FALSE)),法术书目录!$Q$1:$R$10,2,FALSE),"") | V14: =法术书目录!H7 | X14: =IF(法术书目录!G52<>"QuQ",AD14,"") | Y14: =IFERROR(VLOOKUP((VLOOKUP(AA14,列表!$B:$T,13,FALSE)),法术书目录!$Q$1:$R$10,2,FALSE),"") | Z14: =法术书目录!H52 | AC14: 7 | AD14: 52
T15: =IF(法术书目录!G8<>"QuQ",AC15,"") | U15: =IFERROR(VLOOKUP((VLOOKUP(W15,列表!$B:$T,13,FALSE)),法术书目录!$Q$1:$R$10,2,FALSE),"") | V15: =法术书目录!H8 | X15: =IF(法术书目录!G53<>"QuQ",AD15,"") | Y15: =IFERROR(VLOOKUP((VLOOKUP(AA15,列表!$B:$T,13,FALSE)),法术书目录!$Q$1:$R$10,2,FALSE),"") | Z15: =法术书目录!H53 | AC15: 8 | AD15: 53
T16: =IF(法术书目录!G9<>"QuQ",AC16,"") | U16: =IFERROR(VLOOKUP((VLOOKUP(W16,列表!$B:$T,13,FALSE)),法术书目录!$Q$1:$R$10,2,FALSE),"") | V16: =法术书目录!H9 | X16: =IF(法术书目录!G54<>"QuQ",AD16,"") | Y16: =IFERROR(VLOOKUP((VLOOKUP(AA16,列表!$B:$T,13,FALSE)),法术书目录!$Q$1:$R$10,2,FALSE),"") | Z16: =法术书目录!H54 | AC16: 9 | AD16: 54
T17: =IF(法术书目录!G10<>"QuQ",AC17,"") | U17: =IFERROR(VLOOKUP((VLOOKUP(W17,列表!$B:$T,13,FALSE)),法术书目录!$Q$1:$R$10,2,FALSE),"") | V17: =法术书目录!H10 | X17: =IF(法术书目录!G55<>"QuQ",AD17,"") | Y17: =IFERROR(VLOOKUP((VLOOKUP(AA17,列表!$B:$T,13,FALSE)),法术书目录!$Q$1:$R$10,2,FALSE),"") | Z17: =法术书目录!H55 | AC17: 10 | AD17: 55
T18: =IF(法术书目录!G11<>"QuQ",AC18,"") | U18: =IFERROR(VLOOKUP((VLOOKUP(W18,列表!$B:$T,13,FALSE)),法术书目录!$Q$1:$R$10,2,FALSE),"") | V18: =法术书目录!H11 | X18: =IF(法术书目录!G56<>"QuQ",AD18,"") | Y18: =IFERROR(VLOOKUP((VLOOKUP(AA18,列表!$B:$T,13,FALSE)),法术书目录!$Q$1:$R$10,2,FALSE),"") | Z18: =法术书目录!H56 | AC18: 11 | AD18: 56
C19: =IF(E19<>"","持续时间：","") | E19: =IFERROR(VLOOKUP(C3,列表!$B:$T,8,FALSE),"") | T19: =IF(法术书目录!G12<>"QuQ",AC19,"") | U19: =IFERROR(VLOOKUP((VLOOKUP(W19,列表!$B:$T,13,FALSE)),法术书目录!$Q$1:$R$10,2,FALSE),"") | V19: =法术书目录!H12 | X19: =IF(法术书目录!G57<>"QuQ",AD19,"") | Y19: =IFERROR(VLOOKUP((VLOOKUP(AA19,列表!$B:$T,13,FALSE)),法术书目录!$Q$1:$R$10,2,FALSE),"") | Z19: =法术书目录!H57 | AC19: 12 | AD19: 57
T20: =IF(法术书目录!G13<>"QuQ",AC20,"") | U20: =IFERROR(VLOOKUP((VLOOKUP(W20,列表!$B:$T,13,FALSE)),法术书目录!$Q$1:$R$10,2,FALSE),"") | V20: =法术书目录!H13 | X20: =IF(法术书目录!G58<>"QuQ",AD20,"") | Y20: =IFERROR(VLOOKUP((VLOOKUP(AA20,列表!$B:$T,13,FALSE)),法术书目录!$Q$1:$R$10,2,FALSE),"") | Z20: =法术书目录!H58 | AC20: 13 | AD20: 58
T21: =IF(法术书目录!G14<>"QuQ",AC21,"") | U21: =IFERROR(VLOOKUP((VLOOKUP(W21,列表!$B:$T,13,FALSE)),法术书目录!$Q$1:$R$10,2,FALSE),"") | V21: =法术书目录!H14 | X21: =IF(法术书目录!G59<>"QuQ",AD21,"") | Y21: =IFERROR(VLOOKUP((VLOOKUP(AA21,列表!$B:$T,13,FALSE)),法术书目录!$Q$1:$R$10,2,FALSE),"") | Z21: =法术书目录!H59 | AC21: 14 | AD21: 59
C22: =IF(C23<>"","法术说明","") | T22: =IF(法术书目录!G15<>"QuQ",AC22,"") | U22: =IFERROR(VLOOKUP((VLOOKUP(W22,列表!$B:$T,13,FALSE)),法术书目录!$Q$1:$R$10,2,FALSE),"") | V22: =法术书目录!H15 | X22: =IF(法术书目录!G60<>"QuQ",AD22,"") | Y22: =IFERROR(VLOOKUP((VLOOKUP(AA22,列表!$B:$T,13,FALSE)),法术书目录!$Q$1:$R$10,2,FALSE),"") | Z22: =法术书目录!H60 | AC22: 15 | AD22: 60
C23: =IFERROR(VLOOKUP(C3,列表!$B:$T,9,FALSE),"") | T23: =IF(法术书目录!G16<>"QuQ",AC23,"") | U23: =IFERROR(VLOOKUP((VLOOKUP(W23,列表!$B:$T,13,FALSE)),法术书目录!$Q$1:$R$10,2,FALSE),"") | V23: =法术书目录!H16 | X23: =IF(法术书目录!G61<>"QuQ",AD23,"") | Y23: =IFERROR(VLOOKUP((VLOOKUP(AA23,列表!$B:$T,13,FALSE)),法术书目录!$Q$1:$R$10,2,FALSE),"") | Z23: =法术书目录!H61 | AC23: 16 | AD23: 61
T24: =IF(法术书目录!G17<>"QuQ",AC24,"") | U24: =IFERROR(VLOOKUP((VLOOKUP(W24,列表!$B:$T,13,FALSE)),法术书目录!$Q$1:$R$10,2,FALSE),"") | V24: =法术书目录!H17 | X24: =IF(法术书目录!G62<>"QuQ",AD24,"") | Y24: =IFERROR(VLOOKUP((VLOOKUP(AA24,列表!$B:$T,13,FALSE)),法术书目录!$Q$1:$R$10,2,FALSE),"") | Z24: =法术书目录!H62 | AC24: 17 | AD24: 62
T25: =IF(法术书目录!G18<>"QuQ",AC25,"") | U25: =IFERROR(VLOOKUP((VLOOKUP(W25,列表!$B:$T,13,FALSE)),法术书目录!$Q$1:$R$10,2,FALSE),"") | V25: =法术书目录!H18 | X25: =IF(法术书目录!G63<>"QuQ",AD25,"") | Y25: =IFERROR(VLOOKUP((VLOOKUP(AA25,列表!$B:$T,13,FALSE)),法术书目录!$Q$1:$R$10,2,FALSE),"") | Z25: =法术书目录!H63 | AC25: 18 | AD25: 63
T26: =IF(法术书目录!G19<>"QuQ",AC26,"") | U26: =IFERROR(VLOOKUP((VLOOKUP(W26,列表!$B:$T,13,FALSE)),法术书目录!$Q$1:$R$10,2,FALSE),"") | V26: =法术书目录!H19 | X26: =IF(法术书目录!G64<>"QuQ",AD26,"") | Y26: =IFERROR(VLOOKUP((VLOOKUP(AA26,列表!$B:$T,13,FALSE)),法术书目录!$Q$1:$R$10,2,FALSE),"") | Z26: =法术书目录!H64 | AC26: 19 | AD26: 64
T27: =IF(法术书目录!G20<>"QuQ",AC27,"") | U27: =IFERROR(VLOOKUP((VLOOKUP(W27,列表!$B:$T,13,FALSE)),法术书目录!$Q$1:$R$10,2,FALSE),"") | V27: =法术书目录!H20 | X27: =IF(法术书目录!G65<>"QuQ",AD27,"") | Y27: =IFERROR(VLOOKUP((VLOOKUP(AA27,列表!$B:$T,13,FALSE)),法术书目录!$Q$1:$R$10,2,FALSE),"") | Z27: =法术书目录!H65 | AC27: 20 | AD27: 65
T28: =IF(法术书目录!G21<>"QuQ",AC28,"") | U28: =IFERROR(VLOOKUP((VLOOKUP(W28,列表!$B:$T,13,FALSE)),法术书目录!$Q$1:$R$10,2,FALSE),"") | V28: =法术书目录!H21 | X28: =IF(法术书目录!G66<>"QuQ",AD28,"") | Y28: =IFERROR(VLOOKUP((VLOOKUP(AA28,列表!$B:$T,13,FALSE)),法术书目录!$Q$1:$R$10,2,FALSE),"") | Z28: =法术书目录!H66 | AC28: 21 | AD28: 66
T29: =IF(法术书目录!G22<>"QuQ",AC29,"") | U29: =IFERROR(VLOOKUP((VLOOKUP(W29,列表!$B:$T,13,FALSE)),法术书目录!$Q$1:$R$10,2,FALSE),"") | V29: =法术书目录!H22 | X29: =IF(法术书目录!G67<>"QuQ",AD29,"") | Y29: =IFERROR(VLOOKUP((VLOOKUP(AA29,列表!$B:$T,13,FALSE)),法术书目录!$Q$1:$R$10,2,FALSE),"") | Z29: =法术书目录!H67 | AC29: 22 | AD29: 67
T30: =IF(法术书目录!G23<>"QuQ",AC30,"") | U30: =IFERROR(VLOOKUP((VLOOKUP(W30,列表!$B:$T,13,FALSE)),法术书目录!$Q$1:$R$10,2,FALSE),"") | V30: =法术书目录!H23 | X30: =IF(法术书目录!G68<>"QuQ",AD30,"") | Y30: =IFERROR(VLOOKUP((VLOOKUP(AA30,列表!$B:$T,13,FALSE)),法术书目录!$Q$1:$R$10,2,FALSE),"") | Z30: =法术书目录!H68 | AC30: 23 | AD30: 68
T31: =IF(法术书目录!G24<>"QuQ",AC31,"") | U31: =IFERROR(VLOOKUP((VLOOKUP(W31,列表!$B:$T,13,FALSE)),法术书目录!$Q$1:$R$10,2,FALSE),"") | V31: =法术书目录!H24 | X31: =IF(法术书目录!G69<>"QuQ",AD31,"") | Y31: =IFERROR(VLOOKUP((VLOOKUP(AA31,列表!$B:$T,13,FALSE)),法术书目录!$Q$1:$R$10,2,FALSE),"") | Z31: =法术书目录!H69 | AC31: 24 | AD31: 69
T32: =IF(法术书目录!G25<>"QuQ",AC32,"") | U32: =IFERROR(VLOOKUP((VLOOKUP(W32,列表!$B:$T,13,FALSE)),法术书目录!$Q$1:$R$10,2,FALSE),"") | V32: =法术书目录!H25 | X32: =IF(法术书目录!G70<>"QuQ",AD32,"") | Y32: =IFERROR(VLOOKUP((VLOOKUP(AA32,列表!$B:$T,13,FALSE)),法术书目录!$Q$1:$R$10,2,FALSE),"") | Z32: =法术书目录!H70 | AC32: 25 | AD32: 70
T33: =IF(法术书目录!G26<>"QuQ",AC33,"") | U33: =IFERROR(VLOOKUP((VLOOKUP(W33,列表!$B:$T,13,FALSE)),法术书目录!$Q$1:$R$10,2,FALSE),"") | V33: =法术书目录!H26 | X33: =IF(法术书目录!G71<>"QuQ",AD33,"") | Y33: =IFERROR(VLOOKUP((VLOOKUP(AA33,列表!$B:$T,13,FALSE)),法术书目录!$Q$1:$R$10,2,FALSE),"") | Z33: =法术书目录!H71 | AC33: 26 | AD33: 71
T34: =IF(法术书目录!G27<>"QuQ",AC34,"") | U34: =IFERROR(VLOOKUP((VLOOKUP(W34,列表!$B:$T,13,FALSE)),法术书目录!$Q$1:$R$10,2,FALSE),"") | V34: =法术书目录!H27 | X34: =IF(法术书目录!G72<>"QuQ",AD34,"") | Y34: =IFERROR(VLOOKUP((VLOOKUP(AA34,列表!$B:$T,13,FALSE)),法术书目录!$Q$1:$R$10,2,FALSE),"") | Z34: =法术书目录!H72 | AC34: 27 | AD34: 72
T35: =IF(法术书目录!G28<>"QuQ",AC35,"") | U35: =IFERROR(VLOOKUP((VLOOKUP(W35,列表!$B:$T,13,FALSE)),法术书目录!$Q$1:$R$10,2,FALSE),"") | V35: =法术书目录!H28 | X35: =IF(法术书目录!G73<>"QuQ",AD35,"") | Y35: =IFERROR(VLOOKUP((VLOOKUP(AA35,列表!$B:$T,13,FALSE)),法术书目录!$Q$1:$R$10,2,FALSE),"") | Z35: =法术书目录!H73 | AC35: 28 | AD35: 73
